Workbook

Sheet README
A1: Verified-only CSV audit, figures, and source data
A3: Metric | B3: Value
A4: Submitted CSV rows audited | B4: =SUM('Audit Summary'!B2:B4) -> 147
A5: Input rows retained or corrected | B5: =SUM('Audit Summary'!C2:C4) -> 6
A6: Input rows excluded | B6: =SUM('Audit Summary'!D2:D4) -> 141
A7: Verified data-scale output records | B7: =COUNTA('Verified Data Scale'!A2:A8) -> 7
A8: Verified real-robot task records | B8: =COUNTA('World-Gymnast'!A2:A5) -> 4
A9: Submitted columns assessed | B9: =COUNTA('Column Decisions'!A2:A52) -> 51
A11: Decision | B11: Rationale
A12: Exclude corpus_master.csv | B12: All 106 rows are manuscript-derived and lack row-level primary-source URLs, locators, and field-level verification.
A13: Exclude evidence_edges.csv | B13: All 34 edges are manuscript-derived; mixed coding semantics and missing source locators prevent publication-authentic use.
A14: Remove RT-1 hours | B14: The submitted value is an episode-duration assumption, not a source-reported hour measurement.
A15: Correct bound semantics | B15: Cosmos is approximate; V-JEPA 2 and pi_0 are lower bounds; V-JEPA 2-AC is an upper bound.
A16: Correct Dreamer 4 | B16: Use the exact 2,541-hour VPT pool and represent the 100-hour paired-action condition separately.
A17: Retain two figure families | B17: Keep the qualified scale plot and the source-reported World-Gymnast real-robot comparison; omit unsupported ranking and evidence-count plots.
A19: Interpretation warning
A20: The scale values describe different measurement scopes (raw collections, pretraining pools, released robot data, and experimental subsets). They must not be interpreted as a sample-efficiency leaderboard. Only the fields present in the verified sheets are approved for reuse.

Sheet Audit Summary
A1: input_file | B1: input_rows | C1: retained_or_corrected_input_rows | D1: excluded_input_rows | E1: verified_output_rows | F1: audit_conclusion | G1: retention_rate (derived) | H1: reconciliation
A2: corpus_master.csv | B2: 106 | C2: 0 | D2: 106 | E2: 0 | F2: No rows retained because field-level primary-source traceability is absent. | G2: =IF(B2=0,0,C2/B2) -> 0 | H2: =IF(B2=C2+D2,"PASS","CHECK") -> PASS
A3: evidence_edges.csv | B3: 34 | C3: 0 | D3: 34 | E3: 0 | F3: No rows retained because field-level primary-source traceability is absent. | G3: =IF(B3=0,0,C3/B3) -> 0 | H3: =IF(B3=C3+D3,"PASS","CHECK") -> PASS
A4: data_scaling.csv | B4: 7 | C4: 6 | D4: 1 | E4: 7 | F4: Only primary-source-verified scale claims retained; one row split into two claims. | G4: =IF(B4=0,0,C4/B4) -> 0.85714286 | H4: =IF(B4=C4+D4,"PASS","CHECK") -> PASS

Sheet Verified Data Scale
A1: record_id | B1: system | C1: measurement_scope | D1: data_role | E1: reported_hours | F1: bound_type | G1: source_version | H1: source_locator | I1: source_url | J1: verification_date | K1: verification_status | L1: log10_hours (derived)
A2: cosmos_raw | B2: Cosmos WFM | C2: raw candidate video collection | D2: raw_video_collection | E2: 20000000 | F2: approximate | G2: arXiv:2501.03575v3 | H2: Sections 1 and 3.1 | I2: https://arxiv.org/html/2501.03575 | J2: 2026-08-26 | K2: verified_primary_source | L2: =LOG10(E2) -> 7.30103
A3: vjepa2_pretrain | B3: V-JEPA 2 | C3: internet-video pretraining pool | D3: internet_video_pretraining | E3: 1000000 | F3: lower_bound | G3: arXiv:2506.09985v1 | H3: Abstract and Section 2 | I3: https://arxiv.org/html/2506.09985 | J3: 2026-08-26 | K3: verified_primary_source | L3: =LOG10(E3) -> 6
A4: pi0_pretrain | B4: pi_0 | C4: robot-data pretraining mixture | D4: robot_demonstration_pretraining | E4: 10000 | F4: lower_bound | G4: arXiv:2410.24164v4 | H4: Introduction and conclusion | I4: https://arxiv.org/html/2410.24164v4 | J4: 2026-08-26 | K4: verified_primary_source | L4: =LOG10(E4) -> 4
A5: dreamer4_video | B5: Dreamer 4 | C5: VPT gameplay-video pool | D5: gameplay_video_pool | E5: 2541 | F5: exact | G5: arXiv:2509.24527v1 | H5: Section 4.3 and Appendix: Minecraft VPT | I5: https://arxiv.org/pdf/2509.24527 | J5: 2026-08-26 | K5: verified_primary_source | L5: =LOG10(E5) -> 3.4050047
A6: droid_full | B6: DROID | C6: full robot-interaction dataset | D6: robot_interaction_dataset | E6: 350 | F6: exact | G6: arXiv:2403.12945v2 | H6: Abstract | I6: https://arxiv.org/html/2403.12945v2 | J6: 2026-08-26 | K6: verified_primary_source | L6: =LOG10(E6) -> 2.544068
A7: dreamer4_actions | B7: Dreamer 4 | C7: paired-action ablation subset | D7: action_conditioning_ablation | E7: 100 | F7: exact | G7: arXiv:2509.24527v1 | H7: Section 4.3 and Figure 7 | I7: https://arxiv.org/pdf/2509.24527 | J7: 2026-08-26 | K7: verified_primary_source | L7: =LOG10(E7) -> 2
A8: vjepa2_ac | B8: V-JEPA 2-AC | C8: filtered robot-video subset with end-effector states and derived actions | D8: robot_video_with_derived_actions | E8: 62 | F8: upper_bound | G8: arXiv:2506.09985v1 | H8: Abstract and Section 3.1 | I8: https://arxiv.org/html/2506.09985 | J8: 2026-08-26 | K8: verified_primary_source | L8: =LOG10(E8) -> 1.7923917

Sheet World-Gymnast
A1: task | B1: baseline_system | C1: baseline_mean_pct | D1: baseline_se_pct | E1: proposed_system | F1: proposed_mean_pct | G1: proposed_se_pct | H1: trials_per_evaluation | I1: repeated_evaluations | J1: evaluation_protocol | K1: source_version | L1: source_locator | M1: source_url | N1: verification_date | O1: verification_status | P1: delta_pp (derived) | Q1: direction (derived)
A2: Open the drawer | B2: SIMPLER | C2: 34 | D2: 7 | E2: World-Gymnast | F2: 58 | G2: 4 | H2: 10 | I2: 5 | J2: AutoEval real-robot evaluation | K2: arXiv:2602.02454v1 | L2: Section 4.1 and Table 1 | M2: https://arxiv.org/html/2602.02454v1 | N2: 2026-08-26 | O2: verified_primary_source | P2: =F2-C2 -> 24 | Q2: =IF(P2>0,"favors World-Gymnast",IF(P2<0,"favors SIMPLER","tie")) -> favors World-Gymnast
A3: Close the drawer | B3: SIMPLER | C3: 74 | D3: 5 | E3: World-Gymnast | F3: 62 | G3: 6 | H3: 10 | I3: 5 | J3: AutoEval real-robot evaluation | K3: arXiv:2602.02454v1 | L3: Section 4.1 and Table 1 | M3: https://arxiv.org/html/2602.02454v1 | N3: 2026-08-26 | O3: verified_primary_source | P3: =F3-C3 -> -12 | Q3: =IF(P3>0,"favors World-Gymnast",IF(P3<0,"favors SIMPLER","tie")) -> favors SIMPLER
A4: Put the eggplant into the blue sink | B4: SIMPLER | C4: 32 | D4: 10 | E4: World-Gymnast | F4: 72 | G4: 10 | H4: 10 | I4: 5 | J4: AutoEval real-robot evaluation | K4: arXiv:2602.02454v1 | L4: Section 4.1 and Table 1 | M4: https://arxiv.org/html/2602.02454v1 | N4: 2026-08-26 | O4: verified_primary_source | P4: =F4-C4 -> 40 | Q4: =IF(P4>0,"favors World-Gymnast",IF(P4<0,"favors SIMPLER","tie")) -> favors World-Gymnast
A5: Put the eggplant into the yellow basket | B5: SIMPLER | C5: 40 | D5: 10 | E5: World-Gymnast | F5: 78 | G5: 2 | H5: 10 | I5: 5 | J5: AutoEval real-robot evaluation | K5: arXiv:2602.02454v1 | L5: Section 4.1 and Table 1 | M5: https://arxiv.org/html/2602.02454v1 | N5: 2026-08-26 | O5: verified_primary_source | P5: =F5-C5 -> 38 | Q5: =IF(P5>0,"favors World-Gymnast",IF(P5<0,"favors SIMPLER","tie")) -> favors World-Gymnast

Sheet Verified Sources
A1: source_id | B1: system_or_dataset | C1: title | D1: source_version_date | E1: source_version | F1: source_url | G1: verification_date | H1: verification_status
A2: cosmos | B2: Cosmos WFM | C2: Cosmos World Foundation Model Platform for Physical AI | D2: 2025-07-09 | E2: arXiv:2501.03575v3 | F2: https://arxiv.org/html/2501.03575 | G2: 2026-08-26 | H2: verified_primary_source
A3: vjepa2 | B3: V-JEPA 2 / V-JEPA 2-AC | C3: V-JEPA 2: Self-Supervised Video Models Enable Understanding, Prediction and Planning | D3: 2025-06-11 | E3: arXiv:2506.09985v1 | F3: https://arxiv.org/html/2506.09985 | G3: 2026-08-26 | H3: verified_primary_source
A4: pi0 | B4: pi_0 | C4: pi_0: A Vision-Language-Action Flow Model for General Robot Control | D4: 2026-01-08 | E4: arXiv:2410.24164v4 | F4: https://arxiv.org/html/2410.24164v4 | G4: 2026-08-26 | H4: verified_primary_source
A5: dreamer4 | B5: Dreamer 4 | C5: Training Agents Inside of Scalable World Models | D5: 2025-09-29 | E5: arXiv:2509.24527v1 | F5: https://arxiv.org/pdf/2509.24527 | G5: 2026-08-26 | H5: verified_primary_source
A6: droid | B6: DROID | C6: DROID: A Large-Scale In-The-Wild Robot Manipulation Dataset | D6: 2025-04-22 | E6: arXiv:2403.12945v2 | F6: https://arxiv.org/html/2403.12945v2 | G6: 2026-08-26 | H6: verified_primary_source
A7: world_gymnast | B7: World-Gymnast | C7: World-Gymnast: Training Robots with Reinforcement Learning in a World Model | D7: 2026-02-02 | E7: arXiv:2602.02454v1 | F7: https://arxiv.org/html/2602.02454v1 | G7: 2026-08-26 | H7: verified_primary_source

Sheet Source Verification
A1: claim_id | B1: claim_type | C1: submitted_representation | D1: verified_representation | E1: decision | F1: source_locator | G1: source_url | H1: verification_date
A2: cosmos_raw | B2: data scale | C2: 20M presented without a bound | D2: approximately 20M hours | E2: qualifier_corrected | F2: Sections 1 and 3.1 | G2: https://arxiv.org/html/2501.03575 | H2: 2026-08-26
A3: vjepa2_pretrain | B3: data scale | C3: 1M presented as exact | D3: over 1M hours | E3: bound_corrected | F3: Abstract and Section 2 | G3: https://arxiv.org/html/2506.09985 | H3: 2026-08-26
A4: pi0_pretrain | B4: data scale | C4: 10k presented as exact | D4: over 10,000 hours | E4: bound_corrected | F4: Introduction and conclusion | G4: https://arxiv.org/html/2410.24164v4 | H4: 2026-08-26
A5: dreamer4_video | B5: data scale | C5: rounded gameplay-video pool | D5: 2,541 hours | E5: value_corrected | F5: Section 4.3 and Appendix: Minecraft VPT | G5: https://arxiv.org/pdf/2509.24527 | H5: 2026-08-26
A6: dreamer4_actions | B6: data scale | C6: paired-action quantity embedded in a note | D6: 100-hour paired-action condition | E6: claim_split | F6: Section 4.3 and Figure 7 | G6: https://arxiv.org/pdf/2509.24527 | H6: 2026-08-26
A7: droid_full | B7: data scale | C7: 350 hours | D7: 350 hours | E7: retained | F7: Abstract | G7: https://arxiv.org/html/2403.12945v2 | H7: 2026-08-26
A8: vjepa2_ac | B8: data scale | C8: 62 presented as exact | D8: less than 62 hours with end-effector states and derived actions | E8: bound_and_role_corrected | F8: Abstract and Section 3.1 | G8: https://arxiv.org/html/2506.09985 | H8: 2026-08-26
A9: rt1_estimate | B9: data scale | C9: episode-to-hour author estimate | D9: removed | E9: excluded_not_primary_measurement | F9: No reported-hour locator | G9: https://arxiv.org/abs/2212.06817 | H9: 2026-08-26
A10: world_gymnast_open_the_drawer | B10: real-robot success comparison | C10: prior verified extraction | D10: SIMPLER 34±7%; World-Gymnast 58±4% | E10: retained | F10: Section 4.1 and Table 1 | G10: https://arxiv.org/html/2602.02454v1 | H10: 2026-08-26
A11: world_gymnast_close_the_drawer | B11: real-robot success comparison | C11: prior verified extraction | D11: SIMPLER 74±5%; World-Gymnast 62±6% | E11: retained | F11: Section 4.1 and Table 1 | G11: https://arxiv.org/html/2602.02454v1 | H11: 2026-08-26
A12: world_gymnast_put_the_eggplant_into_the_blue_sink | B12: real-robot success comparison | C12: prior verified extraction | D12: SIMPLER 32±10%; World-Gymnast 72±10% | E12: retained | F12: Section 4.1 and Table 1 | G12: https://arxiv.org/html/2602.02454v1 | H12: 2026-08-26
A13: world_gymnast_put_the_eggplant_into_the_yellow_basket | B13: real-robot success comparison | C13: prior verified extraction | D13: SIMPLER 40±10%; World-Gymnast 78±2% | E13: retained | F13: Section 4.1 and Table 1 | G13: https://arxiv.org/html/2602.02454v1 | H13: 2026-08-26

Sheet Record Decisions
A1: input_file | B1: input_row_id | C1: decision | D1: retained_output_id | E1: reason
A2: corpus_master.csv | B2: rt1 | C2: excluded_unverified_record | E2: Record is manuscript-derived and lacks record-level primary-source URL, locator, and field-level verification.
A3: corpus_master.csv | B3: rt2 | C3: excluded_unverified_record | E3: Record is manuscript-derived and lacks record-level primary-source URL, locator, and field-level verification.
A4: corpus_master.csv | B4: oxe | C4: excluded_unverified_record | E4: Record is manuscript-derived and lacks record-level primary-source URL, locator, and field-level verification.
A5: corpus_master.csv | B5: openvla | C5: excluded_unverified_record | E5: Record is manuscript-derived and lacks record-level primary-source URL, locator, and field-level verification.
A6: corpus_master.csv | B6: fast | C6: excluded_unverified_record | E6: Record is manuscript-derived and lacks record-level primary-source URL, locator, and field-level verification.
A7: corpus_master.csv | B7: openvlaoft | C7: excluded_unverified_record | E7: Record is manuscript-derived and lacks record-level primary-source URL, locator, and field-level verification.
A8: corpus_master.csv | B8: octo | C8: excluded_unverified_record | E8: Record is manuscript-derived and lacks record-level primary-source URL, locator, and field-level verification.
A9: corpus_master.csv | B9: pi0 | C9: excluded_unverified_record | E9: Record is manuscript-derived and lacks record-level primary-source URL, locator, and field-level verification.
A10: corpus_master.csv | B10: rdt1b | C10: excluded_unverified_record | E10: Record is manuscript-derived and lacks record-level primary-source URL, locator, and field-level verification.
A11: corpus_master.csv | B11: groot | C11: excluded_unverified_record | E11: Record is manuscript-derived and lacks record-level primary-source URL, locator, and field-level verification.
A12: corpus_master.csv | B12: pi05 | C12: excluded_unverified_record | E12: Record is manuscript-derived and lacks record-level primary-source URL, locator, and field-level verification.
A13: corpus_master.csv | B13: gr2 | C13: excluded_unverified_record | E13: Record is manuscript-derived and lacks record-level primary-source URL, locator, and field-level verification.
... A141: evidence_edges.csv | B141: E034 | C141: excluded_unverified_edge | E141: Edge is manuscript-derived; source locator, independent verification, and normalized evidence semantics are absent.
A142: data_scaling.csv | B142: cosmos::Cosmos WFM | C142: retained_with_qualifier | D142: cosmos_raw | E142: Primary paper reports about 20M hours; encoded as approximate raw collection scale.
A143: data_scaling.csv | B143: vjepa2::V-JEPA 2 | C143: retained_with_qualifier | D143: vjepa2_pretrain | E143: Primary paper reports over 1M hours; encoded as a lower bound.
A144: data_scaling.csv | B144: pi0::pi_0 | C144: retained_with_qualifier | D144: pi0_pretrain | E144: Primary paper reports over 10,000 hours; encoded as a lower bound.
A145: data_scaling.csv | B145: dreamer4::Dreamer 4 | C145: corrected_and_split | D145: dreamer4_video;dreamer4_actions | E145: Video pool corrected to 2,541 hours; 100-hour paired-action condition represented separately.
A146: data_scaling.csv | B146: rt1::RT-1 | C146: excluded_author_estimate | E146: The hour value is an episode-duration conversion, not a primary-source-reported measurement.
A147: data_scaling.csv | B147: droid::DROID | C147: retained | D147: droid_full | E147: Primary paper reports 350 hours of interaction data.
A148: data_scaling.csv | B148: vjepa2::V-JEPA 2-AC | C148: retained_with_qualifier | D148: vjepa2_ac | E148: Primary paper reports less than 62 hours; encoded as an upper bound.

Sheet Column Decisions
A1: input_file | B1: input_column | C1: decision | D1: reason
A2: corpus_master.csv | B2: bib_key | C2: audit_identifier_only | D2: Retained only in the exclusion log, not as a scientific field.
A3: corpus_master.csv | B3: system_name | C3: excluded | D3: No field-level primary-source URL, locator, and independent verification in the submitted CSV.
A4: corpus_master.csv | B4: family | C4: excluded | D4: No field-level primary-source URL, locator, and independent verification in the submitted CSV.
A5: corpus_master.csv | B5: year | C5: excluded | D5: No field-level primary-source URL, locator, and independent verification in the submitted CSV.
A6: corpus_master.csv | B6: primary_group | C6: excluded | D6: No field-level primary-source URL, locator, and independent verification in the submitted CSV.
A7: corpus_master.csv | B7: secondary_labels | C7: excluded | D7: No field-level primary-source URL, locator, and independent verification in the submitted CSV.
A8: corpus_master.csv | B8: wm_role_label | C8: excluded | D8: No field-level primary-source URL, locator, and independent verification in the submitted CSV.
A9: corpus_master.csv | B9: corpus_status | C9: excluded | D9: No field-level primary-source URL, locator, and independent verification in the submitted CSV.
A10: corpus_master.csv | B10: backbone_or_substrate | C10: excluded | D10: No field-level primary-source URL, locator, and independent verification in the submitted CSV.
A11: corpus_master.csv | B11: action_representation | C11: excluded | D11: No field-level primary-source URL, locator, and independent verification in the submitted CSV.
A12: corpus_master.csv | B12: state_space | C12: excluded | D12: No field-level primary-source URL, locator, and independent verification in the submitted CSV.
... A52: data_scaling.csv | B52: note | C52: excluded_or_replaced | D52: Unsupported ratios and estimates were removed; source-backed scope is recorded separately.

Sheet Figures
A1: Publication-ready figures generated from verified-only data
A2: Vector PDFs and 600-dpi PNGs are included separately in the final package.
A4: Scale label | B4: log10(hours) | C4: bound type
A5: ='Verified Data Scale'!B2&" — "&'Verified Data Scale'!C2 -> Cosmos WFM — raw candidate video collection | B5: ='Verified Data Scale'!L2 -> 7.30103 | C5: ='Verified Data Scale'!F2 -> approximate
A6: ='Verified Data Scale'!B3&" — "&'Verified Data Scale'!C3 -> V-JEPA 2 — internet-video pretraining pool | B6: ='Verified Data Scale'!L3 -> 6 | C6: ='Verified Data Scale'!F3 -> lower_bound
A7: ='Verified Data Scale'!B4&" — "&'Verified Data Scale'!C4 -> pi_0 — robot-data pretraining mixture | B7: ='Verified Data Scale'!L4 -> 4 | C7: ='Verified Data Scale'!F4 -> lower_bound
A8: ='Verified Data Scale'!B5&" — "&'Verified Data Scale'!C5 -> Dreamer 4 — VPT gameplay-video pool | B8: ='Verified Data Scale'!L5 -> 3.4050047 | C8: ='Verified Data Scale'!F5 -> exact
A9: ='Verified Data Scale'!B6&" — "&'Verified Data Scale'!C6 -> DROID — full robot-interaction dataset | B9: ='Verified Data Scale'!L6 -> 2.544068 | C9: ='Verified Data Scale'!F6 -> exact
A10: ='Verified Data Scale'!B7&" — "&'Verified Data Scale'!C7 -> Dreamer 4 — paired-action ablation subset | B10: ='Verified Data Scale'!L7 -> 2 | C10: ='Verified Data Scale'!F7 -> exact
A11: ='Verified Data Scale'!B8&" — "&'Verified Data Scale'!C8 -> V-JEPA 2-AC — filtered robot-video subset with end-effector states and derived actions | B11: ='Verified Data Scale'!L8 -> 1.7923917 | C11: ='Verified Data Scale'!F8 -> upper_bound
A23: Task | B23: SIMPLER | C23: World-Gymnast
A24: ='World-Gymnast'!A2 -> Open the drawer | B24: ='World-Gymnast'!C2 -> 34 | C24: ='World-Gymnast'!F2 -> 58
A25: ='World-Gymnast'!A3 -> Close the drawer | B25: ='World-Gymnast'!C3 -> 74 | C25: ='World-Gymnast'!F3 -> 62
A26: ='World-Gymnast'!A4 -> Put the eggplant into the blue sink | B26: ='World-Gymnast'!C4 -> 32 | C26: ='World-Gymnast'!F4 -> 72
A27: ='World-Gymnast'!A5 -> Put the eggplant into the yellow basket | B27: ='World-Gymnast'!C5 -> 40 | C27: ='World-Gymnast'!F5 -> 78

Sheet Plot Index
A1: file | B1: format | C1: resolution | D1: source data | E1: recommended use
A2: verified_data_scale.pdf | B2: Vector PDF | C2: embedded TrueType fonts | D2: Verified Data Scale | E2: Main text L3; preserve scope and bound caveat
A3: verified_data_scale.png | B3: PNG | C3: 600 dpi | D3: Verified Data Scale | E3: Preview or raster-only workflow
A4: verified_world_gymnast_real_robot.pdf | B4: Vector PDF | C4: embedded TrueType fonts | D4: World-Gymnast | E4: Main text or supplement
A5: verified_world_gymnast_real_robot.png | B5: PNG | C5: 600 dpi | D5: World-Gymnast | E5: Preview or raster-only workflow

Sheet Cited Papers
A1: Cited papers and sources
A3: Cited references | C3: =COUNTA(K9:K183) -> 175 | D3: Compiled from the current 29-page draft on 24 September 2026. | F3: Paper citations | G3: =COUNTIFS(G9:G183,"Paper") -> 169
A4: Unresolved decisions | C4: =C3-COUNTIFS(H9:H183,"Include")-COUNTIFS(H9:H183,"Background")-COUNTIFS(H9:H183,"Exclude")-COUNTIFS(H9:H183,"Duplicate") -> 175 | D4: References and years follow the draft. Use the links and metadata notes to check source details. | F4: Other technical sources | G4: =COUNTIFS(G9:G183,"Technical release / software") -> 6
A5: Marked Include | C5: =COUNTIFS(H9:H183,"Include") -> 0 | D5: Choose Include, Background, Exclude or Duplicate in the amber Review decision column.
A6: Figure 3 count | C6: =IF(C4>0,"Not finalized",C5) -> Not finalized | D6: Settle Pending, blank or invalid decisions before using the count for Figure 3. Extend count ranges if adding rows.
A8: Ref. | B8: Year (as cited) | C8: Reference (as cited) | D8: Two-sentence summary | E8: Primary source link | F8: Topic / role | G8: Source type | H8: Review decision | I8: Decision reason | J8: Report ID | K8: Citation key | L8: Metadata notes | M8: Summary basis
A9: 1 | B9: 2023 | C9: B. Zitkovich, T. Yu, S. Xu, P. Xu, T. Xiao, F. Xia, J. Wu, P. Wohlhart, S. Welker, A. Wahid et al., “RT-2: Vision-language-action models transfer web knowledge to robotic control,” in Proc. Conf. Robot Learn. (CoRL), 2023, arXiv:2307.15818. | D9: RT-2 represents robot actions as tokens and co-trains on robotic trajectories and vision-language tasks. It studies how knowledge learned from web data transfers into language-conditioned manipulation. | E9: https://arxiv.org/abs/2307.15818 | F9: VLA/action policy | G9: Paper | H9: Pending | J9: arXiv:2307.15818 | K9: rt2 | M9: Previously primary-source-checked README catalogue and manuscript discussion; no new quantitative claims.
A10: 2 | B10: 2024 | C10: M. J. Kim, K. Pertsch, S. Karamcheti, T. Xiao, A. Balakrishna, S. Nair, R. Rafailov, E. Foster, G. Lam, P. Sanketi et al., “OpenVLA: An open-source vision-language-action model,” in Proc. Conf. Robot Learn. (CoRL), 2024, arXiv:2406.09246. | D10: OpenVLA combines pretrained visual-language representations with autoregressive robot-action prediction in an open model. It provides a generalist manipulation policy that can be adapted to new tasks through fine-tuning. | E10: https://arxiv.org/abs/2406.09246 | F10: VLA/action policy | G10: Paper | H10: Pending | J10: arXiv:2406.09246 | K10: openvla | M10: Previously primary-source-checked README catalogue and manuscript discussion; no new quantitative claims.
A11: 3 | B11: 2024 | C11: Open X-Embodiment Collaboration, “Open X-Embodiment: Robotic learning datasets and RT-X models,” in Proc. IEEE Int. Conf. Robot. Autom. (ICRA), 2024, arXiv:2310.08864. | D11: Open X-Embodiment brings together robot demonstration datasets collected across different embodiments. The accompanying RT-X models examine whether training on this combined data improves transfer between robotic platforms. | E11: https://arxiv.org/abs/2310.08864 | F11: Dataset/benchmark | G11: Paper | H11: Pending | J11: arXiv:2310.08864 | K11: oxe | L11: Hybrid dataset/model report: OXE and RT-X are one cited report; category reflects its dataset role. | M11: Previously primary-source-checked README catalogue and manuscript discussion; no new quantitative claims.
A12: 4 | B12: 2025 | C12: K. Black, N. Brown, D. Driess, A. Esmail, M. Equi, C. Finn, N. Fusai, L. Groom, K. Hausman, B. Ichter et al., “π0: A vision-language-action flow model for general robot control,” in Proc. Robot.: Sci. Syst. (RSS), 2025, arXiv:2410.24164. | D12: The π0 model couples a pretrained vision-language backbone to a flow-matching action expert. It generates continuous action chunks for manipulation across tasks and robot embodiments. | E12: https://arxiv.org/abs/2410.24164 | F12: VLA/action policy | G12: Paper | H12: Pending | J12: arXiv:2410.24164 | K12: pi0 | M12: Previously primary-source-checked README catalogue and manuscript discussion; no new quantitative claims.
A13: 5 | B13: 2025 | C13: J. Bjorck, F. Castañeda, N. Cherniadev, X. Da, R. Ding, L. Fan, Y. Fang, D. Fox, F. Hu, S. Huang et al., “GR00T N1: An open foundation model for generalist humanoid robots,” arXiv preprint, 2025, arXiv:2503.14734. | D13: GR00T N1 combines vision-language interpretation with diffusion-based action generation for humanoid robots. Its dual-system design connects slower semantic processing with continuous control. | E13: https://arxiv.org/abs/2503.14734 | F13: VLA/action policy | G13: Paper | H13: Pending | J13: arXiv:2503.14734 | K13: groot | M13: Previously primary-source-checked README catalogue and manuscript discussion; no new quantitative claims.
A14: 6 | B14: 2025 | C14: Gemini Robotics Team, “Gemini Robotics: Bringing AI into the physical world,” arXiv preprint, 2025, arXiv:2503.20020. | D14: Gemini Robotics extends a Gemini vision-language model to generate robot actions from observations and instructions. The developer-reported study examines manipulation capabilities and transfer across embodiments. | E14: https://arxiv.org/abs/2503.20020 | F14: VLA/action policy | G14: Paper | H14: Pending | J14: arXiv:2503.20020 | K14: geminirobotics | L14: Vendor-authored technical research paper, not reclassified as nonpaper simply because evidence is vendor-reported. | M14: Previously primary-source-checked README catalogue and manuscript discussion; no new quantitative claims.
A15: 7 | B15: 2025 | C15: Figure AI, “Helix: A vision-language-action model for generalist humanoid control,” Figure AI technical blog, , 2025. | D15: Helix combines a slower vision-language component with a faster continuous-action controller for humanoid upper-body manipulation. The cited vendor release describes this dual-system architecture and its demonstrated behaviors. | E15: https://www.figure.ai/news/helix | F15: Vendor technical release | G15: Technical release / software | H15: Pending | J15: https://www.figure.ai/news/helix | K15: helix | M15: Previously primary-source-checked README catalogue and manuscript discussion; no new quantitative claims.
A16: 8 | B16: 2025 | C16: M. J. Kim, C. Finn, and P. Liang, “Fine-tuning vision-languageaction models: Optimizing speed and success,” arXiv preprint, 2025, arXiv:2502.19645. | D16: OpenVLA-OFT studies fine-tuning choices for faster and more successful VLA control. Its recipe uses action chunking and parallel continuous regression instead of sequential action-token decoding. | E16: https://arxiv.org/abs/2502.19645 | F16: Policy training/adaptation method | G16: Paper | H16: Pending | J16: arXiv:2502.19645 | K16: openvlaoft | M16: Previously primary-source-checked README catalogue and manuscript discussion; no new quantitative claims.
A17: 9 | B17: 2025 | C17: S. Fei, S. Wang, J. Shi, Z. Dai, J. Cai, P. Qian, L. Ji, X. He, S. Zhang, Z. Fei et al., “LIBERO-Plus: In-depth robustness analysis of vision-language-action models,” arXiv preprint, 2025, arXiv:2510.13626. | D17: LIBERO-Plus probes manipulation policies with controlled visual, physical-configuration, and instruction perturbations. Its instruction-removal and goal-replacement tests distinguish apparent language robustness from reliable instruction grounding. | E17: https://arxiv.org/abs/2510.13626 | F17: Dataset/benchmark | G17: Paper | H17: Pending | J17: arXiv:2510.13626 | K17: liberoplus | M17: Previously primary-source-checked README catalogue and manuscript discussion; no new quantitative claims.
A18: 10 | B18: 2025 | C18: A. Jain, M. Zhang, K. Arora, W. Chen, M. Torne, M. Z. Irshad, S. Zakharov, Y. Wang, S. Levine, C. Finn et al., “PolaRiS: Scalable real-to-sim evaluations for generalist robot policies,” arXiv preprint, 2025, arXiv:2512.16881. | D18: PolaRiS reconstructs interactive simulation environments from short scans of real scenes for robot-policy evaluation. Paired simulated and physical tests examine how well these evaluations predict real-world performance. | E18: https://arxiv.org/abs/2512.16881 | F18: Dataset/benchmark | G18: Paper | H18: Pending | J18: arXiv:2512.16881 | K18: polaris | L18: Evaluation framework/method paper grouped with benchmark/evaluation sources; not a mere data file. | M18: Primary-source abstract or article and manuscript context; source reviewed 2026-09-24.
A19: 11 | B19: 2026 | C19: H. Li, Y. Zuo, J. Yu, Y. Zhang, Z. Yang, K. Zhang, X. Zhu, Y. Zhang, T. Chen, G. Cui et al., “SimpleVLA-RL: Scaling VLA training via reinforcement learning,” in Proc. Int. Conf. Learn. Representations (ICLR), 2026, arXiv:2509.09674. | D19: SimpleVLA-RL adapts VLA policies through online reinforcement learning with stochastic action-token decoding. It evaluates how interaction changes performance under different demonstration budgets. | E19: https://arxiv.org/abs/2509.09674 | F19: Policy training/adaptation method | G19: Paper | H19: Pending | J19: arXiv:2509.09674 | K19: simplevlarl | M19: Previously primary-source-checked README catalogue and manuscript discussion; no new quantitative claims.
A20: 12 | B20: 2025 | C20: S. Tan, K. Dou, Y. Zhao, and P. Krähenbühl, “Interactive post-training for vision-language-action models,” arXiv preprint, 2025, arXiv:2505.17016. | D20: RIPT-VLA fine-tunes pretrained robot policies through reinforcement learning with sparse task-success rewards. It studies interactive post-training of both lightweight and larger policies under limited supervision. | E20: https://arxiv.org/abs/2505.17016 | F20: Policy training/adaptation method | G20: Paper | H20: Pending | J20: arXiv:2505.17016 | K20: riptvla | M20: Previously primary-source-checked README catalogue and manuscript discussion; no new quantitative claims.
A21: 13 | B21: 2025 | C21: M. Assran, A. Bardes, D. Fan, Q. Garrido, R. Howes, M. Komeili, M. Muckley, A. Rizvi, C. Roberts, K. Sinha et al., “V-JEPA 2: Selfsupervised video models enable understanding, prediction and planning,” arXiv preprint, 2025, arXiv:2506.09985. | D21: V-JEPA 2 learns predictive video representations from action-free video at scale. Its separately adapted V-JEPA 2-AC model predicts action-conditioned latent transitions for planning toward image goals. | E21: https://arxiv.org/abs/2506.09985 | F21: World model/predictive system | G21: Paper | H21: Pending | J21: arXiv:2506.09985 | K21: vjepa2 | M21: Previously primary-source-checked README catalogue and manuscript discussion; no new quantitative claims.
A22: 14 | B22: 2025 | C22: J. Jang, S. Ye, Z. Lin, J. Xiang, J. Bjorck, Y. Fang, F. Hu, S. Huang, K. Kundalia, Y.-C. Lin et al., “DreamGen: Unlocking generalization in robot learning through video world models,” arXiv preprint, 2025, arXiv:2505.12705. | D22: DreamGen generates task-conditioned robot videos and obtains pseudo-action labels through inverse dynamics. The resulting synthetic trajectories augment policy training as an offline data-generation pipeline. | E22: https://arxiv.org/abs/2505.12705 | F22: World model/predictive system | G22: Paper | H22: Pending | J22: arXiv:2505.12705 | K22: dreamgen | M22: Previously primary-source-checked README catalogue and manuscript discussion; no new quantitative claims.
A23: 15 | B23: 2025 | C23: D. Hafner, W. Yan, and T. Lillicrap, “Training agents inside of scalable world models,” arXiv preprint, 2025, arXiv:2509.24527. | D23: Dreamer 4 trains agents inside a scalable video world model learned from offline data. Its main application is Minecraft, while separate ablations examine the amount of action-labeled video required for prediction. | E23: https://arxiv.org/abs/2509.24527 | F23: World model/predictive system | G23: Paper | H23: Pending | J23: arXiv:2509.24527 | K23: dreamer4 | M23: Previously primary-source-checked README catalogue and manuscript discussion; no new quantitative claims.
A24: 16 | B24: 2025 | C24: J. Cen, C. Yu, H. Yuan, Y. Jiang, S. Huang, J. Guo, X. Li, Y. Song, H. Luo, F. Wang et al., “WorldVLA: Towards autoregressive action world model,” arXiv preprint, 2025, arXiv:2506.21539. | D24: WorldVLA uses shared autoregressive modeling for robot actions and future observations. Its predictive-training experiments provide evidence about joint learning without establishing a general advantage for online candidate-action search. | E24: https://arxiv.org/abs/2506.21539 | F24: World model/predictive system | G24: Paper | H24: Pending | J24: arXiv:2506.21539 | K24: worldvla | M24: Previously primary-source-checked README catalogue and manuscript discussion; no new quantitative claims.
A25: 17 | B25: 2026 | C25: M. J. Kim, Y. Gao, T.-Y. Lin, Y.-C. Lin, Y. Ge, G. Lam, P. Liang, S. Song, M.-Y. Liu, C. Finn, and J. Gu, “Cosmos Policy: Fine-tuning video models for visuomotor control and planning,” in Proc. Int. Conf. Learn. Representations (ICLR), 2026, arXiv:2601.16163. | D25: Cosmos Policy adapts a video model to jointly generate actions, future states, and values. It evaluates direct visuomotor execution alongside rollout refinement and candidate selection for planning. | E25: https://arxiv.org/abs/2601.16163 | F25: World model/predictive system | G25: Paper | H25: Pending | J25: arXiv:2601.16163 | K25: cosmospolicy | M25: Previously primary-source-checked README catalogue and manuscript discussion; no new quantitative claims.
A26: 18 | B26: 2026 | C26: Y. Ma, Z. Song, Y. Zhuang, J. Hao, and I. King, “A survey on vision-language-action models for embodied AI,” IEEE Trans. Neural Netw. Learn. Syst, 2026, arXiv:2405.14093. | D26: This survey organizes VLA research into model components, low-level control policies, and high-level task planners. It also reviews datasets, simulators, and benchmarks that support language-conditioned embodied action. | E26: https://arxiv.org/abs/2405.14093 | F26: Survey | G26: Paper | H26: Pending | J26: arXiv:2405.14093 | K26: ma2024survey | M26: Primary-source abstract or article and manuscript context; source reviewed 2026-09-24.
A27: 19 | B27: 2025 | C27: Y. Zhong, F. Bai, S. Cai, X. Huang, Z. Chen, X. Zhang, Y. Wang, S. Guo, T. Guan, K. N. Lui et al., “A survey on vision-language-action models: An action tokenization perspective,” arXiv preprint, 2025, arXiv:2507.01925. | D27: This survey compares VLA systems through the intermediate representations used to express actions. Its tokenization taxonomy spans language, code, affordances, trajectories, goals, latent codes, raw actions, and reasoning. | E27: https://arxiv.org/abs/2507.01925 | F27: Survey | G27: Paper | H27: Pending | J27: arXiv:2507.01925 | K27: zhong2025token | M27: Primary-source abstract or article and manuscript context; source reviewed 2026-09-24.
A28: 20 | B28: 2025 | C28: K. Kawaharazuka, J. Oh, J. Yamada, I. Posner, and Y. Zhu, “Visionlanguage-action models for robotics: A review towards real-world applications,” IEEE Access, vol. 13, pp. 162 467–162 504, 2025. | D28: This review connects VLA architectures and learning methods with the practical requirements of robot deployment. It covers hardware platforms, data collection, augmentation, datasets, and evaluation alongside model design. | E28: https://arxiv.org/abs/2510.07077 | F28: Survey | G28: Paper | H28: Pending | J28: arXiv:2510.07077 | K28: kawaharazuka2025 | M28: Primary-source abstract or article and manuscript context; source reviewed 2026-09-24.
A29: 21 | B29: 2026 | C29: M. U. Din, W. Akram, L. S. Saoud, J. Rosell, and I. Hussain, “Multimodal fusion with vision-language-action models for robotic manipulation: A systematic review,” Information Fusion, vol. 129, p. 104062, 2026. | D29: This systematic review organizes manipulation VLAs by multimodal fusion strategies, architectures, datasets, and evaluation resources. It also develops an agentic outlook in which planners use VLA skills with verification and diagnostic feedback. | E29: https://doi.org/10.1016/j.inffus.2025.104062 | F29: Survey | G29: Paper | H29: Pending | J29: 10.1016/j.inffus.2025.104062 | K29: din2025priorvlasurvey | M29: Published article abstract and agentic-framework discussion, previously checked in the authors institutional repository.
A30: 22 | B30: 2026 | C30: B. Hou, G. Li, J. Jia, T. An, X. Guo, S. Leng, H. Geng, Y. Ze, T. Harada, P. Torr et al., “World model for robot learning: A comprehensive survey,” arXiv preprint, 2026, arXiv:2605.00080. | D30: This survey reviews world models according to their roles in robot-policy learning, planning, simulation, data generation, and evaluation. It relates policy coupling and controllable video prediction to datasets and experimental protocols across embodied domains. | E30: https://arxiv.org/abs/2605.00080 | F30: Survey | G30: Paper | H30: Pending | J30: arXiv:2605.00080 | K30: hou2026wm | M30: Primary-source abstract or article and manuscript context; source reviewed 2026-09-24.
... A41: 33 | B41: 2025 | C41: J. Ding, Y. Zhang, Y. Shang, Y. Zhang, Z. Zong, J. Feng, Y. Yuan, H. Su, N. Li, N. Sukiennik et al., “Understanding world or predicting future? A comprehensive survey of world models,” ACM Computing Surveys, vol. 58, no. 3, pp. 1–38, 2025. | D41: This survey distinguishes world models that construct internal representations from those that simulate future states. It reviews these roles across robotics, autonomous driving, and other domains and identifies open modeling challenges. | E41: https://doi.org/10.1145/3746449 | F41: Survey | G41: Paper | H41: Pending | J41: https://doi.org/10.1145/3746449 | K41: ding2025worldsurvey | M41: Primary-source abstract or article and manuscript context; source reviewed 2026-09-24.
A42: 34 | B42: 2025 | C42: X. Li et al., “A step toward world models: A survey on robotic manipulation,” arXiv preprint, 2025, arXiv:2511.02097. | D42: This survey examines manipulation methods that exhibit world-model capabilities, including approaches not explicitly labeled as world models. It uses their roles in perception, prediction, and control to identify the components needed for broader predictive robotics. | E42: https://arxiv.org/abs/2511.02097 | F42: Survey | G42: Paper | H42: Pending | J42: arXiv:2511.02097 | K42: li2025step | L42: The as-cited reference lists X. Li et al.; the primary source instead identifies Peng-Fei Zhang and colleagues. Citation number, key and as-cited wording are retained for traceability; the author attribution requires correction in the manuscript bibliography. | M42: Primary-source abstract or article and manuscript context; source reviewed 2026-09-24.
A43: 35 | B43: 2025 | C43: Jiang et al., “A survey on vision-language-action models for autonomous driving,” in Proc. IEEE/CVF Int. Conf. Comput. Vis. Workshops (ICCVW), WDFM-AD, 2025. | D43: This survey reviews vision-language-action architectures for autonomous driving, including their progression toward reasoning-centered control. It compares vehicle-domain datasets and evaluation concerns such as safety, instruction following, and explanation quality. | E43: https://openaccess.thecvf.com/content/ICCV2025W/WDFM-AD/html/Jiang_A_Survey_on_Vision-Language-Action_Models_for_Autonomous_Driving_ICCVW_2025_paper.html | F43: Survey | G43: Paper | H43: Pending | J43: https://openaccess.thecvf.com/content/ICCV2025W/WDFM-AD/html/Jiang_A_Survey_on_Vision-Language-Action_Models_for_Autonomous_Driving_ICCVW_2025_paper.html | K43: jiang2025driving | M43: Primary-source abstract or article and manuscript context; source reviewed 2026-09-24.
A44: 36 | B44: 2025 | C44: D. Zhang, J. Sun, C. Hu, X. Wu, Z. Yuan, R. Zhou, F. Shen, and Q. Zhou, “Pure vision language action (VLA) models: A comprehensive survey,” arXiv preprint, 2025, arXiv:2509.19012. | D44: This survey classifies VLA methods into autoregressive, diffusion, reinforcement-learning, hybrid, and specialized approaches. It connects these design choices to application scenarios, datasets, benchmarks, and simulators. | E44: https://arxiv.org/abs/2509.19012 | F44: Survey | G44: Paper | H44: Pending | J44: arXiv:2509.19012 | K44: zhang2025pure | M44: Primary-source abstract or article and manuscript context; source reviewed 2026-09-24.
A45: 37 | B45: 2021 | C45: M. J. Page, J. E. McKenzie, P. M. Bossuyt, I. Boutron, T. C. Hoffmann, C. D. Mulrow, L. Shamseer, J. M. Tetzlaff, E. A. Akl, S. E. Brennan et al., “The PRISMA 2020 statement: An updated guideline for reporting systematic reviews,” BMJ, vol. 372, p. n71, 2021. | D45: The PRISMA 2020 statement provides reporting guidance for systematic reviews through checklists and flow-diagram templates. It supports transparent reporting of searches, selection, synthesis, and limitations rather than certifying that a review was conducted correctly. | E45: https://doi.org/10.1136/bmj.n71 | F45: Methodology | G45: Paper | H45: Pending | J45: https://doi.org/10.1136/bmj.n71 | K45: prisma2020 | M45: Original statement and official PRISMA statement/checklist descriptions; reviewed 2026-09-24.
A46: 38 | B46: 2023 | C46: A. Brohan, N. Brown, J. Carbajal, Y. Chebotar, J. Dabis, C. Finn, K. Gopalakrishnan, K. Hausman, A. Herzog, J. Hsu et al., “RT-1: Robotics transformer for real-world control at scale,” arXiv preprint, 2023, arXiv:2212.06817. | D46: RT-1 maps camera observations and language instructions to discretized robot commands using a transformer policy. It is an early language-conditioned control precursor to later VLA foundation models. | E46: https://arxiv.org/abs/2212.06817 | F46: VLA/action policy | G46: Paper | H46: Pending | J46: arXiv:2212.06817 | K46: rt1 | M46: Previously primary-source-checked README catalogue and manuscript discussion; no new quantitative claims.
A47: 39 | B47: 2023 | C47: Y. Jiang, A. Gupta, Z. Zhang, G. Wang, Y. Dou, Y. Chen, L. Fei-Fei, A. Anandkumar, Y. Zhu, and L. Fan, “VIMA: General robot manipulation with multimodal prompts,” in International Conference on Machine Learning (ICML), 2023, arXiv:2210.03094. | D47: VIMA specifies manipulation tasks using prompts that interleave text and images. A transformer policy converts these multimodal task descriptions and observations into robot actions. | E47: https://arxiv.org/abs/2210.03094 | F47: VLA/action policy | G47: Paper | H47: Pending | J47: arXiv:2210.03094 | K47: vima | M47: Previously primary-source-checked README catalogue and manuscript discussion; no new quantitative claims.
A48: 40 | B48: 2024 | C48: X. Li, M. Liu, H. Zhang, C. Yu, J. Xu, H. Wu, C. Cheang, Y. Jing, W. Zhang, H. Liu et al., “Vision-language foundation models as effective robot imitators,” in Proc. Int. Conf. Learn. Representations (ICLR), 2024, arXiv:2311.01378. | D48: RoboFlamingo adapts a pretrained OpenFlamingo vision-language model for robot imitation learning. An action-prediction interface connects multimodal understanding to language-conditioned manipulation. | E48: https://arxiv.org/abs/2311.01378 | F48: VLA/action policy | G48: Paper | H48: Pending | J48: arXiv:2311.01378 | K48: roboflamingo | M48: Previously primary-source-checked README catalogue and manuscript discussion; no new quantitative claims.
A49: 41 | B49: 2024 | C49: D. Niu, Y. Sharma, G. Biamby, J. Quenum, Y. Bai, B. Shi, T. Darrell, and R. Herzig, “LLARV A: Vision-action instruction tuning enhances robot learning,” in Proc. Conf. Robot Learn. (CoRL), 2024, arXiv:2406.11815. | D49: LLARVA uses vision-action instruction tuning with intermediate two-dimensional visual traces. These traces help align multimodal representations with the robot behaviors learned during adaptation. | E49: https://arxiv.org/abs/2406.11815 | F49: VLA/action policy | G49: Paper | H49: Pending | J49: arXiv:2406.11815 | K49: llarva | M49: Previously primary-source-checked README catalogue and manuscript discussion; no new quantitative claims.
A50: 42 | B50: 2025 | C50: S. Ye, J. Jang, B. Jeon, S. Joo, J. Yang, B. Peng, A. Mandlekar, R. Tan et al., “Latent action pretraining from videos,” in International Conference on Learning Representations (ICLR), 2025, arXiv:2410.11758. | D50: LAPA learns latent action representations from video without ground-truth action labels during pretraining. Robot data subsequently maps the pretrained policy into executable robot actions. | E50: https://arxiv.org/abs/2410.11758 | F50: VLA/action policy | G50: Paper | H50: Pending | J50: arXiv:2410.11758 | K50: lapa | M50: Previously primary-source-checked README catalogue and manuscript discussion; no new quantitative claims.
A51: 43 | B51: 2025 | C51: K. Pertsch, K. Stachowicz, B. Ichter, D. Driess, S. Nair, Q. Vuong, O. Mees, C. Finn, and S. Levine, “FAST: Efficient action tokenization for vision-language-action models,” in Proc. Robot.: Sci. Syst. (RSS), 2025, arXiv:2501.09747. | D51: FAST compresses continuous action chunks into frequency-domain tokens for autoregressive prediction. The π0-FAST policy demonstrates how this representation can support action generation for dexterous control. | E51: https://arxiv.org/abs/2501.09747 | F51: VLA/action policy | G51: Paper | H51: Pending | J51: arXiv:2501.09747 | K51: fast | M51: Previously primary-source-checked README catalogue and manuscript discussion; no new quantitative claims.
A52: 44 | B52: 2025 | C52: Liang et al., “Discrete diffusion VLA: Bringing discrete diffusion to action decoding in vision-language-action policies,” arXiv preprint, 2025, arXiv:2508.20072. | D52: Discrete Diffusion VLA generates discretized action chunks through iterative diffusion-style refinement within a shared transformer. It explores parallel action decoding as an alternative to sequential autoregressive generation. | E52: https://arxiv.org/abs/2508.20072 | F52: VLA/action policy | G52: Paper | H52: Pending | J52: arXiv:2508.20072 | K52: ddvla | M52: Previously primary-source-checked README catalogue and manuscript discussion; no new quantitative claims.
...

Sheet Current References
A1: Current manuscript references
A3: Cited sources | C3: =COUNTA(B9:B187) -> 179 | D3: References in the manuscript released on 1 October 2026. | G3: Paper sources | H3: =COUNTIFS(G9:G187,"Paper") -> 171
A4: Pending decisions | C4: =COUNTIFS(H9:H187,"Pending") -> 179 | D4: Review decisions are Pending. Citation counts do not establish the 156-report included corpus. | G4: Other technical sources | H4: =COUNTIFS(G9:G187,"Technical release / software") -> 8
D5: The earlier 175-reference Cited Papers sheet is retained unchanged.
A8: Ref. | B8: Citation key | C8: Year (as cited) | D8: Reference (as cited) | E8: Two-sentence summary | F8: Primary source link | G8: Source type | H8: Review decision
A9: 1 | B9: rt2 | C9: 2023 | D9: B. Zitkovich, T. Yu, S. Xu, P. Xu, T. Xiao, F. Xia, J. Wu, P. Wohlhart, S. Welker, A. Wahid et al., “RT-2: Vision-language-action models transfer web knowledge to robotic control,” in Proc. Conf. Robot Learn. (CoRL), 2023, arXiv:2307.15818. | E9: RT-2 represents robot actions as tokens and co-trains on robotic trajectories and vision-language tasks. It studies how knowledge learned from web data transfers into language-conditioned manipulation. | F9: https://arxiv.org/abs/2307.15818 | G9: Paper | H9: Pending
A10: 2 | B10: openvla | C10: 2024 | D10: M. J. Kim, K. Pertsch, S. Karamcheti, T. Xiao, A. Balakrishna, S. Nair, R. Rafailov, E. Foster, G. Lam, P. Sanketi et al., “OpenVLA: An open-source vision-language-action model,” in Proc. Conf. Robot Learn. (CoRL), 2024, arXiv:2406.09246. | E10: OpenVLA combines pretrained visual-language representations with autoregressive robot-action prediction in an open model. It provides a generalist manipulation policy that can be adapted to new tasks through fine-tuning. | F10: https://arxiv.org/abs/2406.09246 | G10: Paper | H10: Pending
A11: 3 | B11: oxe | C11: 2024 | D11: Open X-Embodiment Collaboration, “Open X-Embodiment: Robotic learning datasets and RT-X models,” in Proc. IEEE Int. Conf. Robot. Autom. (ICRA), 2024, arXiv:2310.08864. | E11: Open X-Embodiment brings together robot demonstration datasets collected across different embodiments. The accompanying RT-X models examine whether training on this combined data improves transfer between robotic platforms. | F11: https://arxiv.org/abs/2310.08864 | G11: Paper | H11: Pending
A12: 4 | B12: pi0 | C12: 2025 | D12: K. Black, N. Brown, D. Driess, A. Esmail, M. Equi, C. Finn, N. Fusai, L. Groom, K. Hausman, B. Ichter et al., “π0: A vision-language-action flow model for general robot control,” in Proc. Robot.: Sci. Syst. (RSS), 2025, arXiv:2410.24164. | E12: The π0 model couples a pretrained vision-language backbone to a flow-matching action expert. It generates continuous action chunks for manipulation across tasks and robot embodiments. | F12: https://arxiv.org/abs/2410.24164 | G12: Paper | H12: Pending
A13: 5 | B13: groot | C13: 2025 | D13: J. Bjorck, F. Castañeda, N. Cherniadev, X. Da, R. Ding, L. Fan, Y. Fang, D. Fox, F. Hu, S. Huang et al., “GR00T N1: An open foundation model for generalist humanoid robots,” arXiv preprint arXiv:2503.14734, 2025. | E13: GR00T N1 combines vision-language interpretation with diffusion-based action generation for humanoid robots. Its dual-system design connects slower semantic processing with continuous control. | F13: https://arxiv.org/abs/2503.14734 | G13: Paper | H13: Pending
A14: 6 | B14: geminirobotics | C14: 2025 | D14: Gemini Robotics Team, “Gemini Robotics: Bringing AI into the physical world,” arXiv preprint arXiv:2503.20020, 2025, google DeepMind technical report. | E14: Gemini Robotics extends a Gemini vision-language model to generate robot actions from observations and instructions. The developer-reported study examines manipulation capabilities and transfer across embodiments. | F14: https://arxiv.org/abs/2503.20020 | G14: Paper | H14: Pending
A15: 7 | B15: gemini15 | C15: 2025 | D15: –––, “Gemini Robotics 1.5: Pushing the frontier of generalist robots with advanced embodied reasoning, thinking, and motion transfer,” arXiv preprint arXiv:2510.03342, 2025, google DeepMind technical report. | E15: Gemini Robotics 1.5 integrates embodied reasoning with action generation in a multi-embodiment policy. The developer report also describes transferring motion knowledge across robot configurations. | F15: https://arxiv.org/abs/2510.03342 | G15: Paper | H15: Pending
A16: 8 | B16: openvlaoft | C16: 2025 | D16: M. J. Kim, C. Finn, and P. Liang, “Fine-tuning vision-language-action models: Optimizing speed and success,” arXiv preprint arXiv:2502.19645, 2025. | E16: OpenVLA-OFT studies fine-tuning choices for faster and more successful VLA control. Its recipe uses action chunking and parallel continuous regression instead of sequential action-token decoding. | F16: https://arxiv.org/abs/2502.19645 | G16: Paper | H16: Pending
A17: 9 | B17: liberoplus | C17: 2025 | D17: S. Fei, S. Wang, J. Shi, Z. Dai, J. Cai, P. Qian, L. Ji, X. He, S. Zhang, Z. Fei et al., “LIBERO-Plus: In-depth robustness analysis of vision-language-action models,” arXiv preprint arXiv:2510.13626, 2025. | E17: LIBERO-Plus probes manipulation policies with controlled visual, physical-configuration, and instruction perturbations. Its instruction-removal and goal-replacement tests distinguish apparent language robustness from reliable instruction grounding. | F17: https://arxiv.org/abs/2510.13626 | G17: Paper | H17: Pending
A18: 10 | B18: polaris | C18: 2025 | D18: A. Jain, M. Zhang, K. Arora, W. Chen, M. Torne, M. Z. Irshad, S. Zakharov, Y. Wang, S. Levine, C. Finn et al., “PolaRiS: Scalable real-to-sim evaluations for generalist robot policies,” arXiv preprint arXiv:2512.16881, 2025. | E18: PolaRiS reconstructs interactive simulation environments from short scans of real scenes for robot-policy evaluation. Paired simulated and physical tests examine how well these evaluations predict real-world performance. | F18: https://arxiv.org/abs/2512.16881 | G18: Paper | H18: Pending
A19: 11 | B19: simplevlarl | C19: 2026 | D19: H. Li, Y. Zuo, J. Yu, Y. Zhang, Z. Yang, K. Zhang, X. Zhu, Y. Zhang, T. Chen, G. Cui et al., “SimpleVLA-RL: Scaling VLA training via reinforcement learning,” in Proc. Int. Conf. Learn. Representations (ICLR), 2026, arXiv:2509.09674. | E19: SimpleVLA-RL adapts VLA policies through online reinforcement learning with stochastic action-token decoding. It evaluates how interaction changes performance under different demonstration budgets. | F19: https://arxiv.org/abs/2509.09674 | G19: Paper | H19: Pending
A20: 12 | B20: riptvla | C20: 2025 | D20: S. Tan, K. Dou, Y. Zhao, and P. Krähenbühl, “Interactive post-training for vision-language-action models,” arXiv preprint arXiv:2505.17016, 2025. | E20: RIPT-VLA fine-tunes pretrained robot policies through reinforcement learning with sparse task-success rewards. It studies interactive post-training of both lightweight and larger policies under limited supervision. | F20: https://arxiv.org/abs/2505.17016 | G20: Paper | H20: Pending
... A187: 179 | B187: ego4d | C187: 2022 | D187: K. Grauman, A. Westbury, E. Byrne, Z. Chavis, A. Furnari, R. Girdhar, J. Hamburger et al., “Ego4D: Around the world in 3,000 hours of egocentric video,” in IEEE/CVF Conference on Computer Vision and Pattern Recognition (CVPR), 2022. | E187: Ego4D collects diverse first-person human video and defines benchmarks for egocentric perception. It provides visual experience relevant to representation learning, distinct from demonstrations labelled with robot-control actions. | F187: https://arxiv.org/abs/2110.07058 | G187: Paper | H187: Pending
