Workbook

Sheet Corpus Summary
B2: Finalized manipulation review corpus
B3: Author-confirmed corpus; three named sources checked and included on 2 October 2026
B5: Primary category | C5: All sources | D5: Screening recommendations | E5: Added included papers | F5: Background | G5: Needs verification | H5: Final included papers
B6: VLA | C6: =COUNTIFS('Literature Register'!$B$2:$B$215,B6) -> 92 | D6: =COUNTIFS('Literature Register'!$B$2:$B$215,B6,'Literature Register'!$H$2:$H$215,"Proposed include",'Literature Register'!$J$2:$J$215,"Paper") -> 69 | E6: =COUNTIFS('Literature Register'!$B$2:$B$215,B6,'Literature Register'!$I$2:$I$215,"Include",'Literature Register'!$J$2:$J$215,"Paper",'Literature Register'!$N$2:$N$215,"<>Current manuscript") -> 9 | F6: =COUNTIFS('Literature Register'!$B$2:$B$215,B6,'Literature Register'!$H$2:$H$215,"Background") -> 18 | G6: =COUNTIFS('Literature Register'!$B$2:$B$215,B6,'Literature Register'!$H$2:$H$215,"Needs verification") -> 0 | H6: =COUNTIFS('Literature Register'!$B$2:$B$215,B6,'Literature Register'!$I$2:$I$215,"Include",'Literature Register'!$J$2:$J$215,"Paper") -> 69
B7: World model | C7: =COUNTIFS('Literature Register'!$B$2:$B$215,B7) -> 55 | D7: =COUNTIFS('Literature Register'!$B$2:$B$215,B7,'Literature Register'!$H$2:$H$215,"Proposed include",'Literature Register'!$J$2:$J$215,"Paper") -> 42 | E7: =COUNTIFS('Literature Register'!$B$2:$B$215,B7,'Literature Register'!$I$2:$I$215,"Include",'Literature Register'!$J$2:$J$215,"Paper",'Literature Register'!$N$2:$N$215,"<>Current manuscript") -> 10 | F7: =COUNTIFS('Literature Register'!$B$2:$B$215,B7,'Literature Register'!$H$2:$H$215,"Background") -> 9 | G7: =COUNTIFS('Literature Register'!$B$2:$B$215,B7,'Literature Register'!$H$2:$H$215,"Needs verification") -> 0 | H7: =COUNTIFS('Literature Register'!$B$2:$B$215,B7,'Literature Register'!$I$2:$I$215,"Include",'Literature Register'!$J$2:$J$215,"Paper") -> 42
B8: Dataset / benchmark | C8: =COUNTIFS('Literature Register'!$B$2:$B$215,B8) -> 39 | D8: =COUNTIFS('Literature Register'!$B$2:$B$215,B8,'Literature Register'!$H$2:$H$215,"Proposed include",'Literature Register'!$J$2:$J$215,"Paper") -> 33 | E8: =COUNTIFS('Literature Register'!$B$2:$B$215,B8,'Literature Register'!$I$2:$I$215,"Include",'Literature Register'!$J$2:$J$215,"Paper",'Literature Register'!$N$2:$N$215,"<>Current manuscript") -> 7 | F8: =COUNTIFS('Literature Register'!$B$2:$B$215,B8,'Literature Register'!$H$2:$H$215,"Background") -> 5 | G8: =COUNTIFS('Literature Register'!$B$2:$B$215,B8,'Literature Register'!$H$2:$H$215,"Needs verification") -> 0 | H8: =COUNTIFS('Literature Register'!$B$2:$B$215,B8,'Literature Register'!$I$2:$I$215,"Include",'Literature Register'!$J$2:$J$215,"Paper") -> 33
B9: Background / other | C9: =COUNTIFS('Literature Register'!$B$2:$B$215,B9) -> 28 | D9: =COUNTIFS('Literature Register'!$B$2:$B$215,B9,'Literature Register'!$H$2:$H$215,"Proposed include",'Literature Register'!$J$2:$J$215,"Paper") -> 0 | E9: =COUNTIFS('Literature Register'!$B$2:$B$215,B9,'Literature Register'!$I$2:$I$215,"Include",'Literature Register'!$J$2:$J$215,"Paper",'Literature Register'!$N$2:$N$215,"<>Current manuscript") -> 0 | F9: =COUNTIFS('Literature Register'!$B$2:$B$215,B9,'Literature Register'!$H$2:$H$215,"Background") -> 28 | G9: =COUNTIFS('Literature Register'!$B$2:$B$215,B9,'Literature Register'!$H$2:$H$215,"Needs verification") -> 0 | H9: =COUNTIFS('Literature Register'!$B$2:$B$215,B9,'Literature Register'!$I$2:$I$215,"Include",'Literature Register'!$J$2:$J$215,"Paper") -> 0
B10: Total distinct sources | C10: =SUM(C6:C9) -> 214 | D10: =SUM(D6:D9) -> 144 | E10: =SUM(E6:E9) -> 26 | F10: =SUM(F6:F9) -> 60 | G10: =SUM(G6:G9) -> 0 | H10: =SUM(H6:H9) -> 144
B12: Other technical/software sources | C12: =COUNTIFS('Literature Register'!$J$2:$J$215,"Technical release / software") -> 10
B13: Primary-source checks recorded | C13: =COUNTIFS('Literature Register'!$P$2:$P$215,"Primary source checked this update") -> 86
B14: Author decisions pending | C14: =COUNTIFS('Literature Register'!$I$2:$I$215,"Pending") -> 0
B15: Current citation keys accounted | C15: 186
B16: Mapped table citation occurrences | C16: 96
B18: Author-confirmed on 2 October 2026: 144 reports comprising 69 VLA, 42 world-model and 33 dataset/benchmark reports.
B19: One source is counted once by arXiv/DOI or primary-report identifier. Hybrid roles remain in Secondary roles.
B20: VLA scope: visual and language-conditioned manipulation policies and directly relevant training/inference methods.
B21: World-model scope: predictive systems with demonstrated relevance to manipulation, learned simulation, or robot control.
B22: Dataset/benchmark scope includes manipulation corpora, data-generation resources, benchmarks, and evaluation studies.
B23: Game-only, general-video, historical, survey, and method-context sources are retained as Background where appropriate.
B24: October 2 checks added three included sources and four contextual Background papers; the corpus remains 144 reports.
B25: Screening recommendations are retained separately. Final included papers are calculated from the Author decision cells.
B26: Use the filters on Literature Register and Table Coverage. All original workbook sheets and quantitative data are preserved.
B27: Year is the first arXiv submission year where available, otherwise the source year. Publication-year differences are in Notes.
B28: Table Coverage adds Seer, VPP and UWM to the retained mapping; R211–R214 are contextual citations outside the corpus.

Sheet Literature Register
A1: Record ID | B1: Primary category | C1: Model / resource | D1: Preprint / source year | E1: Paper / report title | F1: Two-sentence summary | G1: Primary source link | H1: Screening recommendation | I1: Author decision | J1: Source type | K1: Subtype | L1: Secondary roles | M1: Domain scope | N1: Discovery origin | O1: Canonical identifier | P1: Source verification | Q1: Checked date | R1: Source locator | S1: Citation keys | T1: Manuscript locations | U1: Decision reason | V1: Notes
A2: R001 | B2: VLA | C2: 3D-CAVLA | D2: 2025 | E2: 3D CAVLA: Leveraging Depth and 3D Context to Generalize Vision-Language-Action Models for Unseen Tasks | F2: 3D-CAVLA combines depth information, task-relevant visual regions, and intermediate reasoning for VLA adaptation. These cues support manipulation in tasks beyond those seen during training. | G2: https://arxiv.org/abs/2505.05800 | H2: Proposed include | I2: Include | J2: Paper | K2: Language-conditioned spatial manipulation policy | M2: manipulation | N2: Current manuscript | O2: arXiv:2505.05800 | P2: Prior primary-source check retained | R2: Established companion catalogue primary-source trace; not freshly rechecked this update. | S2: cavla | T2: Companion model catalogue; SectionIV | U2: Primary report proposes a visually and linguistically conditioned manipulation policy or a directly evaluated VLA training/inference method.
A3: R002 | B3: VLA | C3: 3D-VLA | D3: 2024 | E3: 3D-VLA: A 3D Vision-Language-Action Generative World Model | F3: 3D-VLA combines three-dimensional vision-language representations with generation of future observations and robot actions. It connects spatial grounding with predictive policy learning for manipulation. | G3: https://arxiv.org/abs/2403.09631 | H3: Proposed include | I3: Include | J3: Paper | K3: Predictive VLA policy | L3: WM / predictive-policy overlap | M3: manipulation | N3: Current manuscript | O3: arXiv:2403.09631 | P3: Prior primary-source check retained | R3: Established companion catalogue primary-source trace; not freshly rechecked this update. | S3: threedvla | T3: Companion model catalogue; SectionIV; Table2/tab:vla-master; tab:vla-master | U3: Primary report proposes a visually and linguistically conditioned manipulation policy or a directly evaluated VLA training/inference method. | V3: One report only; predictive-policy secondary tag does not generate a second WM count.
A4: R003 | B4: VLA | C4: Act3D (language-conditioned 3D policy) | D4: 2023 | E4: Act3D: 3D Feature Field Transformers for Multi-Task Robotic Manipulation | F4: Act3D uses a hierarchical three-dimensional feature field with task-instruction conditioning to predict manipulation actions. Coarse-to-fine spatial sampling concentrates computation where precise action prediction is needed. | G4: https://arxiv.org/abs/2306.17817 | H4: Proposed include | I4: Include | J4: Paper | K4: Language-conditioned spatial manipulation policy | M4: manipulation | N4: Current manuscript | O4: arXiv:2306.17817 | P4: Prior primary-source check retained | R4: Established companion catalogue primary-source trace; not freshly rechecked this update. | S4: act3d | T4: Companion model catalogue; SectionIV | U4: Primary report proposes a visually and linguistically conditioned manipulation policy or a directly evaluated VLA training/inference method.
A5: R004 | B5: VLA | C5: BitVLA | D5: 2025 | E5: BitVLA: 1-Bit Vision-Language-Action Models for Robotics Manipulation | F5: BitVLA combines low-bit model weights with visual-encoder compression to reduce the memory and inference demands of a VLA policy. It addresses resource-efficient manipulation deployment rather than explicit prediction of action consequences. | G5: https://arxiv.org/abs/2506.07530 | H5: Proposed include | I5: Include | J5: Paper | K5: VLA policy | M5: manipulation | N5: Current manuscript | O5: arXiv:2506.07530 | P5: Prior primary-source check retained | R5: Established companion catalogue primary-source trace; not freshly rechecked this update. | S5: bitvla | T5: Companion model catalogue; SectionIV; Table2/tab:vla-master; tab:vla-master | U5: Primary report proposes a visually and linguistically conditioned manipulation policy or a directly evaluated VLA training/inference method.
A6: R005 | B6: VLA | C6: BridgeVLA | D6: 2025 | E6: BridgeVLA: Input-Output Alignment for Efficient 3D Manipulation Learning | F6: BridgeVLA projects three-dimensional observations into multiple image views and predicts spatial action heatmaps. This design aligns visual inputs with the spatial representation of control outputs. | G6: https://arxiv.org/abs/2506.07961 | H6: Proposed include | I6: Include | J6: Paper | K6: Language-conditioned spatial manipulation policy | M6: manipulation | N6: Current manuscript | O6: arXiv:2506.07961 | P6: Prior primary-source check retained | R6: Established companion catalogue primary-source trace; not freshly rechecked this update. | S6: bridgevla | T6: Companion model catalogue; SectionIV | U6: Primary report proposes a visually and linguistically conditioned manipulation policy or a directly evaluated VLA training/inference method.
A7: R006 | B7: VLA | C7: CEED-VLA | D7: 2025 | E7: CEED-VLA: Consistency Vision-Language-Action Model with Early-Exit Decoding | F7: CEED-VLA uses consistency distillation and early-exit decoding to accelerate action-token generation. It studies efficient execution of VLA policies under constrained inference budgets. | G7: https://arxiv.org/abs/2506.13725 | H7: Proposed include | I7: Include | J7: Paper | K7: VLA training / inference method | L7: Efficiency | M7: manipulation | N7: Current manuscript | O7: arXiv:2506.13725 | P7: Prior primary-source check retained | R7: Established companion catalogue primary-source trace; not freshly rechecked this update. | S7: ceedvla | T7: Companion model catalogue; SectionIV | U7: Primary report proposes a visually and linguistically conditioned manipulation policy or a directly evaluated VLA training/inference method.
A8: R007 | B8: VLA | C8: CogACT | D8: 2024 | E8: CogACT: A Foundational Vision-Language-Action Model for Synergizing Cognition and Action in Robotic Manipulation | F8: CogACT couples a vision-language backbone to a specialized diffusion action transformer. This separation connects semantic interpretation with continuous manipulation commands. | G8: https://arxiv.org/abs/2411.19650 | H8: Proposed include | I8: Include | J8: Paper | K8: VLA policy | M8: manipulation | N8: Current manuscript | O8: arXiv:2411.19650 | P8: Prior primary-source check retained | R8: Established companion catalogue primary-source trace; not freshly rechecked this update. | S8: cogact | T8: Companion model catalogue; SectionIV | U8: Primary report proposes a visually and linguistically conditioned manipulation policy or a directly evaluated VLA training/inference method.
A9: R008 | B9: VLA | C9: ConRFT | D9: 2025 | E9: ConRFT: A Reinforced Fine-Tuning Method for VLA Models via Consistency Policy | F9: ConRFT fine-tunes VLA policies through offline and online reinforcement learning with a consistency-based objective. Human intervention during online learning supports adaptation to physical manipulation tasks. | G9: https://arxiv.org/abs/2502.05450 | H9: Proposed include | I9: Include | J9: Paper | K9: VLA reinforcement-learning / preference method | L9: Post-training | M9: manipulation | N9: Current manuscript | O9: arXiv:2502.05450 | P9: Prior primary-source check retained | R9: Established companion catalogue primary-source trace; not freshly rechecked this update. | S9: conrft | T9: Companion model catalogue; SectionIV | U9: Primary report proposes a visually and linguistically conditioned manipulation policy or a directly evaluated VLA training/inference method.
A10: R009 | B10: VLA | C10: CoT-VLA | D10: 2025 | E10: CoT-VLA: Visual Chain-of-Thought Reasoning for Vision-Language-Action Models | F10: CoT-VLA predicts future images as intermediate visual goals before generating action sequences. This visual chain of thought links prediction to policy execution without itself establishing candidate-action search. | G10: https://arxiv.org/abs/2503.22020 | H10: Proposed include | I10: Include | J10: Paper | K10: Predictive VLA policy | L10: WM / predictive-policy overlap | M10: manipulation | N10: Current manuscript | O10: arXiv:2503.22020 | P10: Prior primary-source check retained | R10: Established companion catalogue primary-source trace; not freshly rechecked this update. | S10: cotvla | T10: Companion model catalogue; SectionIV; Table2/tab:vla-master; tab:vla-master | U10: Primary report proposes a visually and linguistically conditioned manipulation policy or a directly evaluated VLA training/inference method. | V10: One report only; predictive-policy secondary tag does not generate a second WM count.
A11: R010 | B11: VLA | C11: DeeR-VLA | D11: 2024 | E11: DeeR-VLA: Dynamic Inference of Multimodal Large Language Models for Efficient Robot Execution | F11: DeeR-VLA equips a multimodal policy backbone with multiple exits so that inference depth can vary with the current input. It links robot execution efficiency to adaptive computation rather than a fixed processing depth. | G11: https://arxiv.org/abs/2411.02359 | H11: Proposed include | I11: Include | J11: Paper | K11: VLA training / inference method | L11: Efficiency | M11: manipulation | N11: Current manuscript | O11: arXiv:2411.02359 | P11: Prior primary-source check retained | R11: Established companion catalogue primary-source trace; not freshly rechecked this update. | S11: deervla | T11: Companion model catalogue; SectionIV | U11: Primary report proposes a visually and linguistically conditioned manipulation policy or a directly evaluated VLA training/inference method.
A12: R011 | B12: VLA | C12: DexVLA | D12: 2025 | E12: DexVLA: Vision-Language Model with Plug-In Diffusion Expert for General Robot Control | F12: DexVLA connects a vision-language backbone to a pretrained diffusion action expert. Its staged training adapts the action-generation component across tasks and robot embodiments. | G12: https://arxiv.org/abs/2502.05855 | H12: Proposed include | I12: Include | J12: Paper | K12: VLA policy | M12: manipulation | N12: Current manuscript | O12: arXiv:2502.05855 | P12: Prior primary-source check retained | R12: Established companion catalogue primary-source trace; not freshly rechecked this update. | S12: dexvla | T12: Companion model catalogue; SectionIV | U12: Primary report proposes a visually and linguistically conditioned manipulation policy or a directly evaluated VLA training/inference method.
A13: R012 | B13: VLA | C13: DiffusionVLA / DiVLA | D13: 2024 | E13: Diffusion-VLA: Generalizable and Interpretable Robot Foundation Model via Self-Generated Reasoning | F13: Combines autoregressive language reasoning with a diffusion module that generates robot actions. A reasoning-injection module connects generated explanations to control, with evaluation across real-robot sorting, grasping and instruction-following tasks. | G13: https://arxiv.org/abs/2412.03293 | H13: Proposed include | I13: Include | J13: Paper | K13: Reasoning-conditioned diffusion VLA | M13: manipulation | N13: Additional search | O13: arXiv:2412.03293 | P13: Primary source checked this update | Q13: 2026-10-01 | R13: arXiv abstract, title and submission history; first-report year used. | S13: diffusionvla | U13: Fresh primary-source search identifies an additional manipulation VLA report absent from the current bibliography and companion catalogue. | V13: Supplementary targeted search, not an exhaustive systematic search.
A14: R013 | B14: VLA | C14: Discrete Diffusion VLA | D14: 2025 | E14: Discrete Diffusion VLA: Bringing Discrete Diffusion to Action Decoding in Vision-Language-Action Policies | F14: Discrete Diffusion VLA generates discretized action chunks through iterative diffusion-style refinement within a shared transformer. It explores parallel action decoding as an alternative to sequential autoregressive generation. | G14: https://arxiv.org/abs/2508.20072 | H14: Proposed include | I14: Include | J14: Paper | K14: VLA policy | M14: manipulation | N14: Current manuscript | O14: arXiv:2508.20072 | P14: Prior primary-source check retained | R14: Established companion catalogue primary-source trace; not freshly rechecked this update. | S14: ddvla | T14: Companion model catalogue; SectionIV | U14: Primary report proposes a visually and linguistically conditioned manipulation policy or a directly evaluated VLA training/inference method.
A15: R014 | B15: VLA | C15: ECoT | D15: 2024 | E15: Robotic Control via Embodied Chain-of-Thought Reasoning | F15: Embodied Chain-of-Thought trains a VLA to generate intermediate plans and visually grounded reasoning before robot actions. The method studies whether explicit reasoning supervision improves control and instruction execution. | G15: https://arxiv.org/abs/2407.08693 | H15: Proposed include | I15: Include | J15: Paper | K15: VLA policy | M15: manipulation | N15: Current manuscript | O15: arXiv:2407.08693 | P15: Prior primary-source check retained | R15: Established companion catalogue primary-source trace; not freshly rechecked this update. | S15: ecot | T15: Companion model catalogue; SectionIV; Table2/tab:vla-master; tab:vla-master | U15: Primary report proposes a visually and linguistically conditioned manipulation policy or a directly evaluated VLA training/inference method.
A16: R015 | B16: VLA | C16: EdgeVLA / EVLA | D16: 2025 | E16: EdgeVLA: Efficient Vision-Language-Action Models for Edge Deployment | F16: EdgeVLA combines a smaller language backbone with non-autoregressive action prediction. It targets reduced inference and memory costs on resource-constrained robot hardware. | G16: https://arxiv.org/abs/2507.14049 | H16: Proposed include | I16: Include | J16: Paper | K16: VLA policy | M16: manipulation | N16: Current manuscript | O16: arXiv:2507.14049 | P16: Prior primary-source check retained | R16: Established companion catalogue primary-source trace; not freshly rechecked this update. | S16: edgevla | T16: Companion model catalogue; SectionIV | U16: Primary report proposes a visually and linguistically conditioned manipulation policy or a directly evaluated VLA training/inference method.
A17: R016 | B17: VLA | C17: EfficientVLA | D17: 2025 | E17: EfficientVLA: Training-Free Acceleration and Compression for Vision-Language-Action Models | F17: EfficientVLA accelerates existing policies through language-layer pruning, visual-token selection, and reuse of diffusion-head features. Its contribution is a training-free reduction of policy inference cost. | G17: https://arxiv.org/abs/2506.10100 | H17: Proposed include | I17: Include | J17: Paper | K17: VLA training / inference method | L17: Efficiency | M17: manipulation | N17: Current manuscript | O17: arXiv:2506.10100 | P17: Prior primary-source check retained | R17: Established companion catalogue primary-source trace; not freshly rechecked this update. | S17: efficientvla | T17: Companion model catalogue; SectionIV | U17: Primary report proposes a visually and linguistically conditioned manipulation policy or a directly evaluated VLA training/inference method.
A18: R017 | B18: VLA | C18: FAST / π0-FAST | D18: 2025 | E18: FAST: Efficient Action Tokenization for Vision-Language-Action Models | F18: FAST compresses continuous action chunks into frequency-domain tokens for autoregressive prediction. The π0-FAST policy demonstrates how this representation can support action generation for dexterous control. | G18: https://arxiv.org/abs/2501.09747 | H18: Proposed include | I18: Include | J18: Paper | K18: Action tokenization method with VLA policy variant | M18: manipulation | N18: Current manuscript | O18: arXiv:2501.09747 | P18: Prior primary-source check retained | R18: Established companion catalogue primary-source trace; not freshly rechecked this update. | S18: fast | T18: Companion model catalogue; SectionIV; Table2/tab:vla-master; tab:vla-master | U18: Primary report proposes a visually and linguistically conditioned manipulation policy or a directly evaluated VLA training/inference method.
A19: R018 | B19: VLA | C19: FLaRe (RL fine-tuning) | D19: 2024 | E19: FLaRe: Achieving Masterful and Adaptive Robot Policies with Large-Scale Reinforcement Learning Fine-Tuning | F19: FLaRe uses large-scale reinforcement-learning fine-tuning to improve pretrained robot policies. It is distinct from FLARE, the separate method for aligning policy features with future latent representations. | G19: https://arxiv.org/abs/2409.16578 | H19: Proposed include | I19: Include | J19: Paper | K19: VLA reinforcement-learning / preference method | L19: Post-training | M19: general robotics | N19: Current manuscript | O19: arXiv:2409.16578 | P19: Primary source checked this update | Q19: 2026-10-01 | R19: Abstract and experiments: RL fine-tuning of embodied robot policies; mobile manipulation in simulation and on physical robots. | S19: flarerl | T19: Companion model catalogue; SectionIV; Table2/tab:vla-master; tab:vla-master | U19: Primary report proposes a visually and linguistically conditioned manipulation policy or a directly evaluated VLA training/inference method. | V19: Year uses first arXiv report (2024); existing reference uses publication year 2025. Simulated embodied tasks include navigation and manipulation; not exclusively physical robot manipulation. Year differs from the manuscript citation; register uses the documented source year.
A20: R019 | B20: VLA | C20: ForceVLA | D20: 2025 | E20: ForceVLA: Enhancing VLA Models with a Force-Aware MoE for Contact-Rich Manipulation | F20: ForceVLA integrates force-torque feedback with vision-language features through a force-aware mixture-of-experts module. It targets contact-rich manipulation where visual information alone may be insufficient. | G20: https://arxiv.org/abs/2505.22159 | H20: Proposed include | I20: Include | J20: Paper | K20: VLA policy | M20: manipulation | N20: Current manuscript | O20: arXiv:2505.22159 | P20: Prior primary-source check retained | R20: Established companion catalogue primary-source trace; not freshly rechecked this update. | S20: forcevla | T20: Companion model catalogue; Other manuscript section | U20: Primary report proposes a visually and linguistically conditioned manipulation policy or a directly evaluated VLA training/inference method.
A21: R020 | B21: VLA | C21: FP3 (language-conditioned 3D policy) | D21: 2025 | E21: FP3: A 3D Foundation Policy for Robotic Manipulation | F21: FP3 pretrains a diffusion-transformer manipulation policy using point clouds, proprioception, and CLIP-encoded instructions. It adapts this language-conditioned three-dimensional policy to downstream tasks. | G21: https://arxiv.org/abs/2503.08950 | H21: Proposed include | I21: Include | J21: Paper | K21: Language-conditioned spatial manipulation policy | M21: manipulation | N21: Current manuscript | O21: arXiv:2503.08950 | P21: Primary source checked this update | Q21: 2026-10-01 | R21: Figure2 and SectionIII-A: point clouds, CLIP language embeddings and proprioception condition denoised action chunks. | S21: fp3 | T21: Companion model catalogue; SectionIV; Table2/tab:vla-master; tab:vla-master | U21: Primary report proposes a visually and linguistically conditioned manipulation policy or a directly evaluated VLA training/inference method.
A22: R021 | B22: VLA | C22: Gemini Robotics | D22: 2025 | E22: Gemini Robotics: Bringing AI into the Physical World | F22: Gemini Robotics extends a Gemini vision-language model to generate robot actions from observations and instructions. The developer-reported study examines manipulation capabilities and transfer across embodiments. | G22: https://arxiv.org/abs/2503.20020 | H22: Proposed include | I22: Include | J22: Paper | K22: VLA policy | M22: general robotics | N22: Current manuscript | O22: arXiv:2503.20020 | P22: Prior primary-source check retained | R22: Established companion catalogue primary-source trace; not freshly rechecked this update. | S22: geminirobotics | T22: Companion model catalogue; SectionIV; Table2/tab:vla-master; tab:vla-master | U22: Primary report proposes a visually and linguistically conditioned manipulation policy or a directly evaluated VLA training/inference method. | V22: Research paper retained despite vendor-origin evaluation; vendor reporting alone is not a non-paper classification.
A23: R022 | B23: VLA | C23: Gemini Robotics 1.5 | D23: 2025 | E23: Gemini Robotics 1.5: Pushing the Frontier of Generalist Robots with Advanced Embodied Reasoning, Thinking, and Motion Transfer | F23: Gemini Robotics 1.5 integrates embodied reasoning with action generation in a multi-embodiment policy. The developer report also describes transferring motion knowledge across robot configurations. | G23: https://arxiv.org/abs/2510.03342 | H23: Proposed include | I23: Include | J23: Paper | K23: VLA policy | M23: general robotics | N23: Current manuscript | O23: arXiv:2510.03342 | P23: Prior primary-source check retained | R23: Established companion catalogue primary-source trace; not freshly rechecked this update. | S23: gemini15 | T23: Companion model catalogue; SectionIV; Table2/tab:vla-master; tab:vla-master | U23: Primary report proposes a visually and linguistically conditioned manipulation policy or a directly evaluated VLA training/inference method. | V23: Research paper retained despite vendor-origin evaluation; vendor reporting alone is not a non-paper classification.
A24: R023 | B24: VLA | C24: GeoVLA | D24: 2025 | E24: GeoVLA: Empowering 3D Representations in Vision-Language-Action Models | F24: GeoVLA fuses image-language representations with point-cloud geometry in an action expert. This spatial interface supplies three-dimensional context for language-conditioned manipulation. | G24: https://arxiv.org/abs/2508.09071 | H24: Proposed include | I24: Include | J24: Paper | K24: Language-conditioned spatial manipulation policy | M24: manipulation | N24: Current manuscript | O24: arXiv:2508.09071 | P24: Prior primary-source check retained | R24: Established companion catalogue primary-source trace; not freshly rechecked this update. | S24: geovla | T24: Companion model catalogue; SectionIV | U24: Primary report proposes a visually and linguistically conditioned manipulation policy or a directly evaluated VLA training/inference method.
A25: R024 | B25: VLA | C25: GR-2 | D25: 2024 | E25: GR-2: A Generative Video-Language-Action Model with Web-Scale Knowledge for Robot Manipulation | F25: GR-2 combines large-scale video pretraining with joint video and action learning for robotic manipulation. Its predictive-policy formulation connects visual knowledge from web video to robot trajectories. | G25: https://arxiv.org/abs/2410.06158 | H25: Proposed include | I25: Include | J25: Paper | K25: Predictive VLA policy | L25: WM / predictive-policy overlap | M25: manipulation | N25: Current manuscript | O25: arXiv:2410.06158 | P25: Prior primary-source check retained | R25: Established companion catalogue primary-source trace; not freshly rechecked this update. | S25: gr2 | T25: Companion model catalogue; SectionIV; Table2/tab:vla-master; tab:vla-master | U25: Primary report proposes a visually and linguistically conditioned manipulation policy or a directly evaluated VLA training/inference method. | V25: One report only; predictive-policy secondary tag does not generate a second WM count. Research paper retained despite vendor-origin evaluation; vendor reporting alone is not a non-paper classification.
A26: R025 | B26: VLA | C26: GR00T N1 | D26: 2025 | E26: GR00T N1: An Open Foundation Model for Generalist Humanoid Robots | F26: GR00T N1 combines vision-language interpretation with diffusion-based action generation for humanoid robots. Its dual-system design connects slower semantic processing with continuous control. | G26: https://arxiv.org/abs/2503.14734 | H26: Proposed include | I26: Include | J26: Paper | K26: VLA policy | M26: general robotics | N26: Current manuscript | O26: arXiv:2503.14734 | P26: Prior primary-source check retained | R26: Established companion catalogue primary-source trace; not freshly rechecked this update. | S26: groot | T26: Companion model catalogue; SectionIV; Table2/tab:vla-master; tab:vla-master | U26: Primary report proposes a visually and linguistically conditioned manipulation policy or a directly evaluated VLA training/inference method.
A27: R026 | B27: VLA | C27: GRAPE | D27: 2024 | E27: GRAPE: Generalizing Robot Policy via Preference Alignment | F27: GRAPE aligns robot policies using trajectory preferences derived from successful and unsuccessful behavior. Task-specific spatial and temporal constraints guide the preference-based training signal. | G27: https://arxiv.org/abs/2411.19309 | H27: Proposed include | I27: Include | J27: Paper | K27: VLA reinforcement-learning / preference method | L27: Post-training | M27: manipulation | N27: Current manuscript | O27: arXiv:2411.19309 | P27: Primary source checked this update | Q27: 2026-10-01 | R27: Abstract: trajectory preferences and constraints align VLA policies. | S27: grape | T27: Companion model catalogue; SectionIV | U27: Primary report proposes a visually and linguistically conditioned manipulation policy or a directly evaluated VLA training/inference method.
A28: R027 | B28: VLA | C28: GraspVLA | D28: 2025 | E28: GraspVLA: A Grasping Foundation Model Pre-Trained on Billion-Scale Synthetic Action Data | F28: GraspVLA combines autoregressive perception with flow-matching action generation for grasping. Its training integrates synthetic robot data with semantic pretraining to support generalizable grasp behavior. | G28: https://arxiv.org/abs/2505.03233 | H28: Proposed include | I28: Include | J28: Paper | K28: Language-conditioned spatial manipulation policy | M28: manipulation | N28: Current manuscript | O28: arXiv:2505.03233 | P28: Prior primary-source check retained | R28: Established companion catalogue primary-source trace; not freshly rechecked this update. | S28: graspvla | T28: Companion model catalogue; SectionIV; Table2/tab:vla-master; tab:vla-master | U28: Primary report proposes a visually and linguistically conditioned manipulation policy or a directly evaluated VLA training/inference method.
A29: R028 | B29: VLA | C29: Hi Robot | D29: 2025 | E29: Hi Robot: Open-Ended Instruction Following with Hierarchical Vision-Language-Action Models | F29: Hi Robot uses hierarchical vision-language-action policies to interpret complex instructions and user feedback. A lower-level controller executes the manipulation steps selected by the higher-level reasoning component. | G29: https://arxiv.org/abs/2502.19417 | H29: Proposed include | I29: Include | J29: Paper | K29: VLA policy | M29: manipulation | N29: Current manuscript | O29: arXiv:2502.19417 | P29: Prior primary-source check retained | R29: Established companion catalogue primary-source trace; not freshly rechecked this update. | S29: hirobot | T29: Companion model catalogue; SectionIV; Table2/tab:vla-master; tab:vla-master | U29: Primary report proposes a visually and linguistically conditioned manipulation policy or a directly evaluated VLA training/inference method.
A30: R029 | B30: VLA | C30: iRe-VLA | D30: 2025 | E30: Improving Vision-Language-Action Model with Online Reinforcement Learning | F30: iRe-VLA alternates reinforcement-learning improvement with supervised learning. This alternating procedure aims to stabilize interactive adaptation of pretrained VLA policies. | G30: https://arxiv.org/abs/2501.16664 | H30: Proposed include | I30: Include | J30: Paper | K30: VLA reinforcement-learning / preference method | L30: Post-training | M30: manipulation | N30: Current manuscript | O30: arXiv:2501.16664 | P30: Prior primary-source check retained | R30: Established companion catalogue primary-source trace; not freshly rechecked this update. | S30: irevla | T30: Companion model catalogue; SectionIV | U30: Primary report proposes a visually and linguistically conditioned manipulation policy or a directly evaluated VLA training/inference method.
A31: R030 | B31: VLA | C31: LAPA | D31: 2024 | E31: Latent Action Pretraining from Videos | F31: LAPA learns latent action representations from video without ground-truth action labels during pretraining. Robot data subsequently maps the pretrained policy into executable robot actions. | G31: https://arxiv.org/abs/2410.11758 | H31: Proposed include | I31: Include | J31: Paper | K31: VLA policy | M31: manipulation | N31: Current manuscript | O31: arXiv:2410.11758 | P31: Prior primary-source check retained | R31: Established companion catalogue primary-source trace; not freshly rechecked this update. | S31: lapa | T31: Companion model catalogue; SectionIV | U31: Primary report proposes a visually and linguistically conditioned manipulation policy or a directly evaluated VLA training/inference method. | V31: Year uses first arXiv report (2024); existing reference uses publication year 2025. Year differs from the manuscript citation; register uses the documented source year.
A32: R031 | B32: VLA | C32: LingBot-VLA | D32: 2026 | E32: A Pragmatic VLA Foundation Model | F32: Trains a generalist VLA on real-world demonstrations from multiple dual-arm robot configurations. The study evaluates cross-platform manipulation and introduces an efficient training implementation and GM-100 evaluation data. | G32: https://arxiv.org/abs/2601.18692 | H32: Proposed include | I32: Include | J32: Paper | K32: Cross-embodiment VLA foundation policy | L32: Dataset / benchmark contribution | M32: manipulation | N32: Additional search | O32: arXiv:2601.18692 | P32: Primary source checked this update | Q32: 2026-10-01 | R32: arXiv abstract, title and submission history; first-report year used. | S32: lingbotvla | U32: Fresh primary-source search identifies an additional manipulation VLA report absent from the current bibliography and companion catalogue. | V32: Supplementary targeted search, not an exhaustive systematic search. Distinct original LingBot-VLA report; not the already-cited LingBot-VLA 2.0 paper.
A33: R032 | B33: VLA | C33: LingBot-VLA 2.0 | D33: 2026 | E33: From Foundation to Application: Improving VLA Models in Practice | F33: LingBot-VLA 2.0 extends a generalist VLA with whole-body action spaces and training across multiple robot embodiments and human videos. Auxiliary future prediction uses video-representation and depth-estimation supervision to connect action learning with temporal and geometric information. | G33: https://arxiv.org/abs/2607.06403 | H33: Proposed include | I33: Include | J33: Paper | K33: Predictive VLA policy | L33: WM / predictive-policy overlap | M33: general robotics | N33: Current manuscript | O33: arXiv:2607.06403 | P33: Prior primary-source check retained | R33: Established companion catalogue primary-source trace; not freshly rechecked this update. | S33: lingbotvla2 | T33: Companion model catalogue; SectionIV; Table2/tab:vla-master; tab:vla-master | U33: Primary report proposes a visually and linguistically conditioned manipulation policy or a directly evaluated VLA training/inference method. | V33: One report only; predictive-policy secondary tag does not generate a second WM count.
A34: R033 | B34: VLA | C34: LLARVA | D34: 2024 | E34: LLARVA: Vision-Action Instruction Tuning Enhances Robot Learning | F34: LLARVA uses vision-action instruction tuning with intermediate two-dimensional visual traces. These traces help align multimodal representations with the robot behaviors learned during adaptation. | G34: https://arxiv.org/abs/2406.11815 | H34: Proposed include | I34: Include | J34: Paper | K34: VLA policy | M34: manipulation | N34: Current manuscript | O34: arXiv:2406.11815 | P34: Prior primary-source check retained | R34: Established companion catalogue primary-source trace; not freshly rechecked this update. | S34: llarva | T34: Companion model catalogue; SectionIV | U34: Primary report proposes a visually and linguistically conditioned manipulation policy or a directly evaluated VLA training/inference method.
A35: R034 | B35: VLA | C35: LoHoVLA | D35: 2025 | E35: LoHoVLA: A Unified Vision-Language-Action Model for Long-Horizon Embodied Tasks | F35: LoHoVLA jointly generates subtask language and robot-action tokens. Hierarchical feedback connects these outputs during multi-step embodied task execution. | G35: https://arxiv.org/abs/2506.00411 | H35: Proposed include | I35: Include | J35: Paper | K35: VLA policy | M35: manipulation | N35: Current manuscript | O35: arXiv:2506.00411 | P35: Prior primary-source check retained | R35: Established companion catalogue primary-source trace; not freshly rechecked this update. | S35: lohovla | T35: Companion model catalogue; SectionIV; Table2/tab:vla-master; tab:vla-master | U35: Primary report proposes a visually and linguistically conditioned manipulation policy or a directly evaluated VLA training/inference method.
A36: R035 | B36: VLA | C36: Long-VLA | D36: 2025 | E36: Long-VLA: Unleashing Long-Horizon Capability of Vision-Language-Action Models | F36: Long-VLA uses phase-aware masking of sensory inputs to support coordination across successive subtasks. It addresses error accumulation and execution over extended manipulation horizons. | G36: https://arxiv.org/abs/2508.19958 | H36: Proposed include | I36: Include | J36: Paper | K36: VLA policy | M36: manipulation | N36: Current manuscript | O36: arXiv:2508.19958 | P36: Prior primary-source check retained | R36: Established companion catalogue primary-source trace; not freshly rechecked this update. | S36: longvla | T36: Companion model catalogue; SectionIV | U36: Primary report proposes a visually and linguistically conditioned manipulation policy or a directly evaluated VLA training/inference method.
A37: R036 | B37: VLA | C37: MemoryVLA | D37: 2025 | E37: MemoryVLA: Perceptual-Cognitive Memory in Vision-Language-Action Models for Robotic Manipulation | F37: MemoryVLA combines perceptual and semantic memory retrieval with a memory-conditioned diffusion action expert. It supplies temporal context for manipulation decisions that cannot be resolved reliably from the current observation alone. | G37: https://arxiv.org/abs/2508.19236 | H37: Proposed include | I37: Include | J37: Paper | K37: VLA policy | M37: manipulation | N37: Current manuscript | O37: arXiv:2508.19236 | P37: Prior primary-source check retained | R37: Established companion catalogue primary-source trace; not freshly rechecked this update. | S37: memoryvla | T37: Companion model catalogue; Other manuscript section | U37: Primary report proposes a visually and linguistically conditioned manipulation policy or a directly evaluated VLA training/inference method.
A38: R037 | B38: VLA | C38: Octo | D38: 2024 | E38: Octo: An Open-Source Generalist Robot Policy | F38: Octo is an open generalist robot policy with a diffusion action head and language- or image-goal conditioning. Its adaptation interface accommodates new observation inputs and robot action spaces. | G38: https://arxiv.org/abs/2405.12213 | H38: Proposed include | I38: Include | J38: Paper | K38: VLA policy | M38: manipulation | N38: Current manuscript | O38: arXiv:2405.12213 | P38: Prior primary-source check retained | R38: Established companion catalogue primary-source trace; not freshly rechecked this update. | S38: octo | T38: Companion model catalogue; SectionIV; Table2/tab:vla-master; tab:vla-master | U38: Primary report proposes a visually and linguistically conditioned manipulation policy or a directly evaluated VLA training/inference method.
A39: R038 | B39: VLA | C39: OneTwoVLA | D39: 2025 | E39: OneTwoVLA: A Unified Vision-Language-Action Model with Adaptive Reasoning | F39: OneTwoVLA unifies explicit reasoning and robot-action generation within one model. It switches between reasoning and execution as task progress requires. | G39: https://arxiv.org/abs/2505.11917 | H39: Proposed include | I39: Include | J39: Paper | K39: VLA policy | M39: manipulation | N39: Current manuscript | O39: arXiv:2505.11917 | P39: Prior primary-source check retained | R39: Established companion catalogue primary-source trace; not freshly rechecked this update. | S39: onetwovla | T39: Companion model catalogue; SectionIV | U39: Primary report proposes a visually and linguistically conditioned manipulation policy or a directly evaluated VLA training/inference method.
A40: R039 | B40: VLA | C40: OpenVLA | D40: 2024 | E40: OpenVLA: An Open-Source Vision-Language-Action Model | F40: OpenVLA combines pretrained visual-language representations with autoregressive robot-action prediction in an open model. It provides a generalist manipulation policy that can be adapted to new tasks through fine-tuning. | G40: https://arxiv.org/abs/2406.09246 | H40: Proposed include | I40: Include | J40: Paper | K40: VLA policy | M40: manipulation | N40: Current manuscript | O40: arXiv:2406.09246 | P40: Prior primary-source check retained | R40: Established companion catalogue primary-source trace; not freshly rechecked this update. | S40: openvla | T40: Companion model catalogue; SectionIV; Table2/tab:vla-master; tab:vla-master | U40: Primary report proposes a visually and linguistically conditioned manipulation policy or a directly evaluated VLA training/inference method.
...

Sheet Table Coverage
A1: Manuscript table | B1: Printed entry | C1: Cited key | D1: Matched record | E1: Primary category | F1: Proposed decision | G1: Matched source title | H1: Source link | I1: Correction / note
A2: VLA models | B2: RT-1 (precursor) | C2: rt1 | D2: R086 | E2: VLA | F2: Background | G2: RT-1: Robotics Transformer for Real-World Control at Scale | H2: https://arxiv.org/abs/2212.06817
A3: VLA models | B3: RT-2 | C3: rt2 | D3: R051 | E3: VLA | F3: Proposed include | G3: RT-2: Vision-Language-Action Models Transfer Web Knowledge to Robotic Control | H3: https://arxiv.org/abs/2307.15818
A4: VLA models | B4: RT-X | C4: oxe | D4: R161 | E4: Dataset / benchmark | F4: Proposed include | G4: Open X-Embodiment: Robotic learning datasets and RT-X models | H4: https://arxiv.org/abs/2310.08864
A5: VLA models | B5: OpenVLA | C5: openvla | D5: R039 | E5: VLA | F5: Proposed include | G5: OpenVLA: An Open-Source Vision-Language-Action Model | H5: https://arxiv.org/abs/2406.09246
A6: VLA models | B6: FAST / π_0-FAST | C6: fast | D6: R017 | E6: VLA | F6: Proposed include | G6: FAST: Efficient Action Tokenization for Vision-Language-Action Models | H6: https://arxiv.org/abs/2501.09747
A7: VLA models | B7: OpenVLA-OFT | C7: openvlaoft | D7: R040 | E7: VLA | F7: Proposed include | G7: Fine-Tuning Vision-Language-Action Models: Optimizing Speed and Success | H7: https://arxiv.org/abs/2502.19645
A8: VLA models | B8: Octo | C8: octo | D8: R037 | E8: VLA | F8: Proposed include | G8: Octo: An Open-Source Generalist Robot Policy | H8: https://arxiv.org/abs/2405.12213
A9: VLA models | B9: π_0 | C9: pi0 | D9: R065 | E9: VLA | F9: Proposed include | G9: π0: A Vision-Language-Action Flow Model for General Robot Control | H9: https://arxiv.org/abs/2410.24164
A10: VLA models | B10: RDT-1B | C10: rdt1b | D10: R045 | E10: VLA | F10: Proposed include | G10: RDT-1B: A Diffusion Foundation Model for Bimanual Manipulation | H10: https://arxiv.org/abs/2410.07864
A11: VLA models | B11: GR00T N1 | C11: groot | D11: R025 | E11: VLA | F11: Proposed include | G11: GR00T N1: An Open Foundation Model for Generalist Humanoid Robots | H11: https://arxiv.org/abs/2503.14734
A12: VLA models | B12: GR00T N1.7 | C12: grootn17 | D12: R073 | E12: VLA | F12: Non-paper source | G12: GR00T-N1.7-3B Model Card | H12: https://huggingface.co/nvidia/GR00T-N1.7-3B
A13: VLA models | B13: π_0.5 | C13: pi05 | D13: R066 | E13: VLA | F13: Proposed include | G13: π0.5: A Vision-Language-Action Model with Open-World Generalization | H13: https://arxiv.org/abs/2504.16054
... A82: Benchmarks | B82: VBench-2.0 | C82: vbench2 | D82: R180 | E82: Dataset / benchmark | F82: Background | G82: VBench-2.0: Advancing video generation benchmark suite for intrinsic faithfulness | H82: https://arxiv.org/abs/2503.21755
A83: Benchmarks | B83: EWMBench | C83: genieenvisioner | D83: R104 | E83: World model | F83: Proposed include | G83: Genie envisioner: A unified world foundation platform for robotic manipulation | H83: https://arxiv.org/abs/2508.05635 | I83: Citation mismatch: table cites Genie Envisioner. Standalone EWMBench paper: R151; https://arxiv.org/abs/2505.09694
A84: Benchmarks | B84: WorldArena | C84: worldarena | D84: R175 | E84: Dataset / benchmark | F84: Proposed include | G84: WorldArena: A unified benchmark for evaluating perception and functional utility of embodied world models | H84: https://arxiv.org/abs/2602.08971
A85: Benchmarks | B85: WorldArena 2.0 | C85: shang2026worldarena2 | D85: R176 | E85: Dataset / benchmark | F85: Proposed include | G85: WorldArena 2.0: Extending embodied world model benchmarking on modality, functionality and platform | H85: https://arxiv.org/abs/2605.17912
A86: Benchmarks | B86: ManipArena | C86: maniparena | D86: R157 | E86: Dataset / benchmark | F86: Proposed include | G86: ManipArena: Comprehensive real-world evaluation of reasoning-oriented generalist robot manipulation | H86: https://arxiv.org/abs/2603.28545
A87: Training datasets | B87: Open X-Embodiment | C87: oxe | D87: R161 | E87: Dataset / benchmark | F87: Proposed include | G87: Open X-Embodiment: Robotic learning datasets and RT-X models | H87: https://arxiv.org/abs/2310.08864
A88: Training datasets | B88: DROID | C88: droid | D88: R150 | E88: Dataset / benchmark | F88: Proposed include | G88: DROID: A large-scale in-the-wild robot manipulation dataset | H88: https://arxiv.org/abs/2403.12945
A89: Training datasets | B89: BridgeData V2 | C89: bridgedata | D89: R146 | E89: Dataset / benchmark | F89: Proposed include | G89: BridgeData V2: A dataset for robot learning at scale | H89: https://arxiv.org/abs/2308.12952
A90: Training datasets | B90: AgiBot World | C90: agibotworld | D90: R144 | E90: Dataset / benchmark | F90: Proposed include | G90: AgiBot World Colosseo: A large-scale manipulation platform for scalable and intelligent embodied systems | H90: https://arxiv.org/abs/2503.06669
A91: Training datasets | B91: LeRobot | C91: cadene2026lerobot | D91: R178 | E91: Dataset / benchmark | F91: Background | G91: LeRobot: An open-source library for end-to-end robot learning | H91: https://arxiv.org/abs/2602.22818
A92: Training datasets | B92: Ego4D | C92: ego4d | D92: R177 | E92: Dataset / benchmark | F92: Background | G92: Ego4D: Around the world in 3,000 hours of egocentric video | H92: https://arxiv.org/abs/2110.07058
A93: Training datasets | B93: VideoMix22M | C93: vjepa2 | D93: R124 | E93: World model | F93: Proposed include | G93: V-JEPA 2: Self-supervised video models enable understanding, prediction and planning | H93: https://arxiv.org/abs/2506.09985
A94: Training datasets | B94: DreamGen traj. | C94: dreamgen | D94: R098 | E94: World model | F94: Proposed include | G94: DreamGen: Unlocking generalization in robot learning through video world models | H94: https://arxiv.org/abs/2505.12705
A95: VLA master | B95: Seer | C95: seer | D95: R208 | E95: VLA | F95: Proposed include | G95: Predictive Inverse Dynamics Models are Scalable Learners for Robotic Manipulation | H95: https://arxiv.org/abs/2412.15109 | I95: Added to manuscript master table on 2 October 2026 after author approval.
A96: VLA master | B96: VPP | C96: vpp | D96: R209 | E96: VLA | F96: Proposed include | G96: Video Prediction Policy: A Generalist Robot Policy with Predictive Visual Representations | H96: https://arxiv.org/abs/2412.14803 | I96: Added to manuscript master table on 2 October 2026 after author approval.
A97: World model master | B97: Unified World Models | C97: uwm | D97: R210 | E97: World model | F97: Proposed include | G97: Unified World Models: Coupling Video and Action Diffusion for Pretraining on Large Robotic Datasets | H97: https://arxiv.org/abs/2504.02792 | I97: Added to manuscript master table on 2 October 2026 after author approval.

Sheet Search Notes
A1: Search date | B1: Research category | C1: Search query / source check | D1: Primary source links | E1: Scope / outcome
A2: 2026-10-01 | B2: VLA | C2: site.arxiv.org RoboVLMs generalist robot policies vision language action | D2: https://arxiv.org/abs/2412.14058; https://robovlms.github.io/ | E2: Targeted search for a missing generalist VLA design study; primary arXiv record opened and checked.
A3: 2026-10-01 | B3: VLA | C3: site.arxiv.org VLA adapter effective vision language action 2025 | D3: https://arxiv.org/abs/2509.09372; https://github.com/OpenHelix-Team/VLA-Adapter | E3: Identified official repository and verified the linked paper; combined with the subsequent exact-name search.
A4: 2026-10-01 | B4: VLA | C4: site.arxiv.org UniVLA learning to act anywhere task centric latent actions | D4: https://arxiv.org/abs/2505.06111; https://www.roboticsproceedings.org/rss21/p014.pdf | E4: Identified RSS report and checked arXiv identity, abstract and first-submission date.
A5: 2026-10-01 | B5: VLA | C5: site.arxiv.org "TinyVLA" "RoboVLMs" "STAR" vision language action | E5: Exploratory query; no new inclusion attributed solely to this query.
A6: 2026-10-01 | B6: VLA | C6: site.arxiv.org "VLA-Adapter" | D6: https://arxiv.org/abs/2509.09372; https://vla-adapter.github.io/ | E6: Exact-name supplementary lookup and primary-paper verification; secondary search hits were not treated as authoritative evidence.
A7: 2026-10-01 | B7: VLA | C7: site.arxiv.org "VLA-0" "Vision-Language" models | D7: https://arxiv.org/abs/2510.13054; https://vla0.github.io/ | E7: Identified VLA-0 and checked primary arXiv record; no performance ranking copied into the register.
A8: 2026-10-01 | B8: VLA | C8: site.arxiv.org "HeteroVLA" | E8: Exploratory query; no HeteroVLA record included because this search did not establish a primary source.
A9: 2026-10-01 | B9: VLA | C9: Direct primary-source lookup: DiffusionVLA | D9: https://arxiv.org/abs/2412.03293 | E9: Known candidate identity opened directly and verified against title, abstract and submission history; no invented web query.
A10: 2026-10-01 | B10: VLA | C10: Direct primary-source follow-up: original LingBot-VLA | D10: https://arxiv.org/abs/2601.18692 | E10: Candidate surfaced in the combined exploratory search output; primary record opened directly. Distinct from LingBot-VLA 2.0.
A11: 2026-10-01 | B11: VLA | C11: Direct source checks for ambiguous policy interfaces and source types | D11: https://arxiv.org/html/2503.08950v1; https://arxiv.org/html/2407.15840v3; https://arxiv.org/html/2411.18623v2; https://arxiv.org/html/2412.09858v1; https://arxiv.org/html/2409.16578v2; https://arxiv.org/abs/2411.19309; https://deepmind.google/blog/gemini-robotics-on-device-brings-ai-to-local-robotic-devices/; https://research.nvidia.com/labs/gear/gr00t-n1_5/; https://www.figure.ai/news/helix; https://arxiv.org/abs/2412.07493v1 | E11: Direct opens and in-document finds; not a database query. Resolved language-conditioning, manipulation scope, method subtype and non-paper technical-source classifications.
A12: 2026-10-01 | B12: World model | C12: site.arxiv.org robot manipulation world model action conditioned RoboDreamer WoVoGen RoboDream 2024 2025 | D12: https://arxiv.org/abs/2404.12377; https://arxiv.org/abs/2504.16464; https://arxiv.org/abs/2606.02577; https://arxiv.org/abs/2609.23578 | E12: Targeted supplementary discovery, not exhaustive database retrieval. Followed primary arXiv records for identity, date and abstract-level eligibility. AR-WAM is an expanded-window September 2026 addition.
A13: 2026-10-01 | B13: World model | C13: site.arxiv.org world model manipulation AVID RoboDreamer GRWM 2025 | D13: https://arxiv.org/abs/2505.10075; https://arxiv.org/abs/2505.11528; https://arxiv.org/abs/2509.22642; https://arxiv.org/abs/2406.14540 | E13: Discovered FlowDreamer, LaDi-WM, WoW and IRASim; primary records subsequently opened. Non-primary aggregator results were not used as final evidence. Other search hits were discovery leads only, not reviewed as an exhaustive candidate pool.
A14: 2026-10-01 | B14: World model | C14: site.arxiv.org/abs "HarmoWAM" | D14: https://arxiv.org/abs/2605.10942 | E14: Verified current manuscript system identity, adaptive predictive/reactive mechanism and real-robot manipulation relevance from primary abstract.
A15: 2026-10-01 | B15: World model | C15: site.arxiv.org/abs "LaWAM" | D15: https://arxiv.org/abs/2606.15768 | E15: Search followed by direct primary arXiv open; checked title, latent-subgoal mechanism and manipulation relevance.
A16: 2026-10-01 | B16: World model | C16: site.arxiv.org/abs "VLA-JEPA" | D16: https://arxiv.org/abs/2602.10098; https://ginwind.github.io/VLA-JEPA/ | E16: Checked primary abstract and official Method Overview; distinguished future supervision from future-frame inputs. Other search results were not incorporated into this finite supplemental set.
A17: 2026-10-01 | B17: World model | C17: site.arxiv.org/abs "TouchWorld" "Tactile-WAM" | D17: https://arxiv.org/abs/2607.07287; https://arxiv.org/abs/2606.26663 | E17: Query was followed by direct opens of both known primary IDs; checked tactile prediction and manipulation evidence separately.
A18: 2026-10-01 | B18: World model | C18: site.arxiv.org "Mastering Diverse Domains" "manipulation" | D18: https://doi.org/10.1038/s41586-025-08744-2; https://arxiv.org/abs/2301.04104 | E18: Primary Nature search result explicitly identifies robot manipulation among evaluation domains. Direct Nature open returned an internal error; arXiv record opened. Nature and arXiv treated as one report.
A19: 2026-10-01 | B19: World model | C19: site.arxiv.org "Genie: Generative Interactive" "robotics" | D19: https://arxiv.org/html/2402.15391v1; https://openreview.net/pdf?id=bJbSbJskOS | E19: Inspected primary Sec. 3.2 robotics-trained model and Sec. 3.3 game policy transfer; supports robotic predictive-system inclusion without claiming physical robot policy transfer.
A20: 2026-10-01 | B20: World model | C20: site.arxiv.org "PlaNet" "manipulation" "1811.04551" | D20: https://arxiv.org/abs/1811.04551 | E20: Direct primary record was also inspected. Retained as historical general continuous-control background under the proposed manipulation-focused core definition.
... A77: 2026-10-02 | B77: Background / other | C77: Direct primary-source check for contextual citation: https://arxiv.org/abs/2203.09634 | D77: https://arxiv.org/abs/2203.09634 | E77: Identity, title, author list, first-report year and planning/recovery role checked during reviewer revision. Retained as Background R214. No new broad search and no change to the 144 included reports.

Sheet README
A1: Verified-only CSV audit, figures, and source data
A3: Metric | B3: Value
A4: Submitted CSV rows audited | B4: =SUM('Audit Summary'!B2:B4) -> 147
A5: Input rows retained or corrected | B5: =SUM('Audit Summary'!C2:C4) -> 6
A6: Input rows excluded | B6: =SUM('Audit Summary'!D2:D4) -> 141
A7: Verified data-scale output records | B7: =COUNTA('Verified Data Scale'!A2:A8) -> 7
A8: Verified real-robot task records | B8: =COUNTA('World-Gymnast'!A2:A5) -> 4
A9: Submitted columns assessed | B9: =COUNTA('Column Decisions'!A2:A52) -> 51
A11: Decision | B11: Rationale
A12: Exclude corpus_master.csv | B12: All 106 rows are manuscript-derived and lack row-level primary-source URLs, locators, and field-level verification.
A13: Exclude evidence_edges.csv | B13: All 34 edges are manuscript-derived; mixed coding semantics and missing source locators prevent publication-authentic use.
A14: Remove RT-1 hours | B14: The submitted value is an episode-duration assumption, not a source-reported hour measurement.
A15: Correct bound semantics | B15: Cosmos is approximate; V-JEPA 2 and pi_0 are lower bounds; V-JEPA 2-AC is an upper bound.
A16: Correct Dreamer 4 | B16: Use the exact 2,541-hour VPT pool and represent the 100-hour paired-action condition separately.
A17: Retain two figure families | B17: Keep the qualified scale plot and the source-reported World-Gymnast real-robot comparison; omit unsupported ranking and evidence-count plots.
A19: Interpretation warning
A20: The scale values describe different measurement scopes (raw collections, pretraining pools, released robot data, and experimental subsets). They must not be interpreted as a sample-efficiency leaderboard. Only the fields present in the verified sheets are approved for reuse.

Sheet Audit Summary
A1: input_file | B1: input_rows | C1: retained_or_corrected_input_rows | D1: excluded_input_rows | E1: verified_output_rows | F1: audit_conclusion | G1: retention_rate (derived) | H1: reconciliation
A2: corpus_master.csv | B2: 106 | C2: 0 | D2: 106 | E2: 0 | F2: No rows retained because field-level primary-source traceability is absent. | G2: =IF(B2=0,0,C2/B2) -> 0 | H2: =IF(B2=C2+D2,"PASS","CHECK") -> PASS
A3: evidence_edges.csv | B3: 34 | C3: 0 | D3: 34 | E3: 0 | F3: No rows retained because field-level primary-source traceability is absent. | G3: =IF(B3=0,0,C3/B3) -> 0 | H3: =IF(B3=C3+D3,"PASS","CHECK") -> PASS
A4: data_scaling.csv | B4: 7 | C4: 6 | D4: 1 | E4: 7 | F4: Only primary-source-verified scale claims retained; one row split into two claims. | G4: =IF(B4=0,0,C4/B4) -> 0.85714286 | H4: =IF(B4=C4+D4,"PASS","CHECK") -> PASS

Sheet Verified Data Scale
A1: record_id | B1: system | C1: measurement_scope | D1: data_role | E1: reported_hours | F1: bound_type | G1: source_version | H1: source_locator | I1: source_url | J1: verification_date | K1: verification_status | L1: log10_hours (derived)
A2: cosmos_raw | B2: Cosmos WFM | C2: raw candidate video collection | D2: raw_video_collection | E2: 20000000 | F2: approximate | G2: arXiv:2501.03575v3 | H2: Sections 1 and 3.1 | I2: https://arxiv.org/html/2501.03575 | J2: 2026-08-26 | K2: verified_primary_source | L2: =LOG10(E2) -> 7.30103
A3: vjepa2_pretrain | B3: V-JEPA 2 | C3: internet-video pretraining pool | D3: internet_video_pretraining | E3: 1000000 | F3: lower_bound | G3: arXiv:2506.09985v1 | H3: Abstract and Section 2 | I3: https://arxiv.org/html/2506.09985 | J3: 2026-08-26 | K3: verified_primary_source | L3: =LOG10(E3) -> 6
